Workbook

Sheet Inputs
A1: Ember Scaling Model v6.8
A4: CASH
A5: Starting cash ($) | B5: 1600000
A6: Fixed costs monthly ($) | B6: 250000
A8: CREDIT CARD
A9: CC limit ($) | B9: 500000
A11: PVX CAPITAL
A12: PVX interest rate | B12: 0.05
A14: FORECAST
A15: Projected ROAS@36 | B15: 2.5
A16: Projected WD ratio | B16: 0.31
A18: GAMING ECONOMICS
A19: Wager volume per $1 net receipts | B19: 28.5
A20: Blended house edge | B20: 0.03
A21: % wager from 3rd party games | B21: 0.3
A22: 3rd party house edge cost | B22: 0.08
A24: AGENCY FEES
A25: Agency fee rate | B25: 0.08
A26: % of ad spend via agency | B26: 0.7
A28: PVX Terms:
A29: - PVX gets 100% of net rev until payback (Cum Paid >= Draw)
A30: - After payback, PVX gets 50% + interest until cap
A31: - Cap = Draw × (1 + Interest Rate)
A32: - After cap hit, Company keeps 100%
A34: 3rd Party Cost Formula:
A35: Total Receipts × Wager/Receipts × House Edge × 3rd Party % × Edge Cost

Sheet Curves
A1: Revenue Curves
A2: 0.5% flat tail per month from month 13-36
A4: Age | B4: Cum R% | C4: Inc R% | D4: Cum W% | E4: Inc W%
A5: 0 | B5: 0.315935 | C5: 0.315935 | D5: 0.13798726 | E5: 0.13798726
A6: 1 | B6: 0.46658363 | C6: 0.15064863 | D6: 0.28981942 | E6: 0.15183216
A7: 2 | B7: 0.56315096 | C7: 0.096567329 | D7: 0.3750433 | E7: 0.085223875
A8: 3 | B8: 0.63109187 | C8: 0.067940906 | D8: 0.46700843 | E8: 0.091965128
A9: 4 | B9: 0.67148476 | C9: 0.040392894 | D9: 0.55942041 | E9: 0.092411982
A10: 5 | B10: 0.70769399 | C10: 0.036209227 | D10: 0.62748327 | E10: 0.068062864
A11: 6 | B11: 0.73896589 | C11: 0.0312719 | D11: 0.71708222 | E11: 0.089598951
A12: 7 | B12: 0.76659636 | C12: 0.02763047 | D12: 0.75640645 | E12: 0.039324228
A13: 8 | B13: 0.79129689 | C13: 0.024700532 | D13: 0.78182533 | E13: 0.025418881
A14: 9 | B14: 0.82 | C14: 0.028703111 | D14: 0.82 | E14: 0.038174668
A15: 10 | B15: 0.84 | C15: 0.02 | D15: 0.84 | E15: 0.02
A16: 11 | B16: 0.86 | C16: 0.02 | D16: 0.86 | E16: 0.02
... A41: 36 | B41: 1 | C41: 0.005 | D41: 1 | E41: 0.005

Sheet Baseline_Decay
A1: Baseline Decay (Fixed Schedule)
A3: Month | B3: Receipts | C3: WD | D3: Net
A4: 0 | B4: 700000 | C4: 350000 | D4: =B4-C4 -> 350000
A5: 1 | B5: 500000 | C5: 250000 | D5: =B5-C5 -> 250000
A6: 2 | B6: 400000 | C6: 200000 | D6: =B6-C6 -> 200000
A7: 3 | B7: 300000 | C7: 150000 | D7: =B7-C7 -> 150000
A8: 4 | B8: 200000 | C8: 100000 | D8: =B8-C8 -> 100000
A9: 5 | B9: 200000 | C9: 100000 | D9: =B9-C9 -> 100000
A10: 6 | B10: 200000 | C10: 100000 | D10: =B10-C10 -> 100000
A11: 7 | B11: 200000 | C11: 100000 | D11: =B11-C11 -> 100000
A12: 8 | B12: 200000 | C12: 100000 | D12: =B12-C12 -> 100000
A13: 9 | B13: 200000 | C13: 100000 | D13: =B13-C13 -> 100000
A14: 10 | B14: 200000 | C14: 100000 | D14: =B14-C14 -> 100000
A15: 11 | B15: 200000 | C15: 100000 | D15: =B15-C15 -> 100000
... A39: 35 | B39: 200000 | C39: 100000 | D39: =B39-C39 -> 100000

Sheet Cohort_Summary
A1: Monthly Cohort Summary
A3: Cohort | B3: Spend | C3: Users | D3: CAC | E3: Age (wks) | F3: Current ROAS | G3: Proj ROAS | H3: Curr Payback | I3: Proj Payback | J3: WD Ratio
A4: 2025-04-01 | B4: 83561.574 | C4: 47087 | D4: 1.7746209 | E4: 42 | F4: 2.5414799 | G4: 3.0993657 | H4: 1.4 | I4: 0.8 | J4: 0.26361038
A5: 2025-05-01 | B5: 77127.49 | C5: 41122 | D5: 1.8755773 | E5: 38 | F5: 3.149368 | G5: 3.9800081 | H5: 1.4 | I5: 0.6 | J5: 0.38310655
A6: 2025-06-01 | B6: 75728.607 | C6: 27893 | D6: 2.7149682 | E6: 34 | F6: 2.7144184 | G6: 3.5408704 | H6: 1.4 | I6: 0.8 | J6: 0.36257797
A7: 2025-07-01 | B7: 130031.25 | C7: 31351 | D7: 4.147595 | E7: 29 | F7: 1.8294541 | G7: 2.4756949 | H7: 5.5 | I7: 4.2 | J7: 0.40330617
A8: 2025-08-01 | B8: 151857.02 | C8: 29508 | D8: 5.1462999 | E8: 25 | F8: 1.8573266 | G8: 2.6244771 | H8: 3.5 | I8: 1.9 | J8: 0.31191477
A9: 2025-09-01 | B9: 179833.77 | C9: 25901 | D9: 6.9431208 | E9: 21 | F9: 1.1475205 | G9: 1.7089301 | I9: 11.9 | J9: 0.33293292
A10: 2025-10-01 | B10: 160252.72 | C10: 24024 | D10: 6.6705261 | E10: 16 | F10: 1.2249096 | G10: 1.9409371 | I10: 4 | J10: 0.23262339
A11: 2025-11-01 | B11: 132959.21 | C11: 23008 | D11: 5.7788251 | E11: 12 | F11: 1.7377281 | G11: 3.0857235 | H11: 2.3 | I11: 1.1 | J11: 0.32002614
A12: 2025-12-01 | B12: 205458.01 | C12: 32217 | D12: 6.3773166 | E12: 8 | F12: 1.1163 | G12: 2.3924972 | I12: 2.4 | J12: 0.29114511
A13: 2026-01-01 | B13: 184702.43 | C13: 30321 | D13: 6.0915679 | E13: 3 | F13: 0.74618209 | G13: 2.3618216 | I13: 1.9 | J13: 0.23856045

Sheet Acquisition_Plan
A1: Acquisition Plan
A3: Month | B3: Total Spend | C3: Use CC | D3: CC Spend | E3: PVX Spend | F3: Cash Spend
A4: 2026-02-01 | B4: 200000 | C4: 1 | D4: 200000 | E4: 0 | F4: =B4-D4-E4 -> 0
A5: 2026-03-03 | B5: 250000 | C5: 1 | D5: =B5 -> 250000 | E5: 0 | F5: =B5-D5-E5 -> 0
A6: 2026-04-02 | B6: 300000 | C6: 1 | D6: 150000 | E6: 150000 | F6: =B6-D6-E6 -> 0
A7: 2026-05-02 | B7: 300000 | C7: 1 | D7: =B7/2 -> 150000 | E7: =B7/2 -> 150000 | F7: =B7-D7-E7 -> 0
A8: 2026-06-01 | B8: 400000 | C8: 1 | D8: =B8/2 -> 200000 | E8: =B8/2 -> 200000 | F8: =B8-D8-E8 -> 0
A9: 2026-07-01 | B9: 400000 | C9: 1 | D9: =B9/2 -> 200000 | E9: =B9/2 -> 200000 | F9: =B9-D9-E9 -> 0
A10: 2026-07-31 | B10: 500000 | C10: 1 | D10: =B10/2 -> 250000 | E10: =B10/2 -> 250000 | F10: =B10-D10-E10 -> 0
A11: 2026-08-30 | B11: 500000 | C11: 1 | D11: =B11/2 -> 250000 | E11: =B11/2 -> 250000 | F11: =B11-D11-E11 -> 0
A12: 2026-09-29 | B12: 600000 | C12: 1 | D12: =B12/2 -> 300000 | E12: =B12/2 -> 300000 | F12: =B12-D12-E12 -> 0
A13: 2026-10-29 | B13: 600000 | C13: 1 | D13: =B13/2 -> 300000 | E13: =B13/2 -> 300000 | F13: =B13-D13-E13 -> 0
A14: 2026-11-28 | B14: 700000 | C14: 1 | D14: =B14/2 -> 350000 | E14: =B14/2 -> 350000 | F14: =B14-D14-E14 -> 0
A15: 2026-12-28 | B15: 700000 | C15: 1 | D15: =B15/2 -> 350000 | E15: =B15/2 -> 350000 | F15: =B15-D15-E15 -> 0
A16: 2027-01-27 | B16: 800000 | C16: 1 | D16: =B16/2 -> 400000 | E16: =B16/2 -> 400000 | F16: =B16-D16-E16 -> 0
A17: 2027-02-26 | B17: 800000 | C17: 1 | D17: =B17/2 -> 400000 | E17: =B17/2 -> 400000 | F17: =B17-D17-E17 -> 0
A18: 2027-03-28 | B18: 800000 | C18: 1 | D18: =B18/2 -> 400000 | E18: =B18/2 -> 400000 | F18: =B18-D18-E18 -> 0
... A39: 2028-12-17 | B39: 800000 | C39: 1 | D39: =B39/2 -> 400000 | E39: =B39/2 -> 400000 | F39: =B39-D39-E39 -> 0

Sheet New_Cohort_Rev
A1: New Cohort Revenue (All Sources)
A2: Spend = CC + Cash + PVX
A4: Cohort | B4: Spend | C4: M0 | D4: M1 | E4: M2 | F4: M3 | G4: M4 | H4: M5 | I4: M6 | J4: M7 | K4: M8 | L4: M9 | M4: M10 | N4: M11 | O4: M12 | P4: M13 | Q4: M14 | R4: M15 | S4: M16 | T4: M17 | U4: M18 | V4: M19 | W4: M20 | X4: M21 | Y4: M22 | Z4: M23 | AA4: M24 | AB4: M25 | AC4: M26 | AD4: M27 | AE4: M28 | AF4: M29 | AG4: M30 | AH4: M31 | AI4: M32 | AJ4: M33 | AK4: M34 | AL4: M35
A5: =Acquisition_Plan!A4 -> 2026-02-01 | B5: =Acquisition_Plan!D4+Acquisition_Plan!F4+Acquisition_Plan!E4 -> 200000 | C5: =$B5*Inputs!$B$15*Curves!$C$5 -> 157967.5 | D5: =$B5*Inputs!$B$15*Curves!$C$6 -> 75324.315 | E5: =$B5*Inputs!$B$15*Curves!$C$7 -> 48283.664 | F5: =$B5*Inputs!$B$15*Curves!$C$8 -> 33970.453 | G5: =$B5*Inputs!$B$15*Curves!$C$9 -> 20196.447 | H5: =$B5*Inputs!$B$15*Curves!$C$10 -> 18104.613 | I5: =$B5*Inputs!$B$15*Curves!$C$11 -> 15635.95 | J5: =$B5*Inputs!$B$15*Curves!$C$12 -> 13815.235 | K5: =$B5*Inputs!$B$15*Curves!$C$13 -> 12350.266 | L5: =$B5*Inputs!$B$15*Curves!$C$14 -> 14351.555 | M5: =$B5*Inputs!$B$15*Curves!$C$15 -> 10000 | N5: =$B5*Inputs!$B$15*Curves!$C$16 -> 10000 | O5: =$B5*Inputs!$B$15*Curves!$C$17 -> 10000 | P5: =$B5*Inputs!$B$15*Curves!$C$18 -> 2500 | Q5: =$B5*Inputs!$B$15*Curves!$C$19 -> 2500 | R5: =$B5*Inputs!$B$15*Curves!$C$20 -> 2500 | S5: =$B5*Inputs!$B$15*Curves!$C$21 -> 2500 | T5: =$B5*Inputs!$B$15*Curves!$C$22 -> 2500 | U5: =$B5*Inputs!$B$15*Curves!$C$23 -> 2500 | V5: =$B5*Inputs!$B$15*Curves!$C$24 -> 2500 | W5: =$B5*Inputs!$B$15*Curves!$C$25 -> 2500 | X5: =$B5*Inputs!$B$15*Curves!$C$26 -> 2500 | Y5: =$B5*Inputs!$B$15*Curves!$C$27 -> 2500 | Z5: =$B5*Inputs!$B$15*Curves!$C$28 -> 2500 | AA5: =$B5*Inputs!$B$15*Curves!$C$29 -> 2500 | AB5: =$B5*Inputs!$B$15*Curves!$C$30 -> 2500 | AC5: =$B5*Inputs!$B$15*Curves!$C$31 -> 2500 | AD5: =$B5*Inputs!$B$15*Curves!$C$32 -> 2500 | AE5: =$B5*Inputs!$B$15*Curves!$C$33 -> 2500 | AF5: =$B5*Inputs!$B$15*Curves!$C$34 -> 2500 | AG5: =$B5*Inputs!$B$15*Curves!$C$35 -> 2500 | AH5: =$B5*Inputs!$B$15*Curves!$C$36 -> 2500 | AI5: =$B5*Inputs!$B$15*Curves!$C$37 -> 2500 | AJ5: =$B5*Inputs!$B$15*Curves!$C$38 -> 2500 | AK5: =$B5*Inputs!$B$15*Curves!$C$39 -> 2500 | AL5: =$B5*Inputs!$B$15*Curves!$C$40 -> 2500
A6: =Acquisition_Plan!A5 -> 2026-03-03 | B6: =Acquisition_Plan!D5+Acquisition_Plan!F5+Acquisition_Plan!E5 -> 250000 | C6: 0 | D6: =$B6*Inputs!$B$15*Curves!$C$5 -> 197459.38 | E6: =$B6*Inputs!$B$15*Curves!$C$6 -> 94155.394 | F6: =$B6*Inputs!$B$15*Curves!$C$7 -> 60354.581 | G6: =$B6*Inputs!$B$15*Curves!$C$8 -> 42463.066 | H6: =$B6*Inputs!$B$15*Curves!$C$9 -> 25245.559 | I6: =$B6*Inputs!$B$15*Curves!$C$10 -> 22630.767 | J6: =$B6*Inputs!$B$15*Curves!$C$11 -> 19544.937 | K6: =$B6*Inputs!$B$15*Curves!$C$12 -> 17269.044 | L6: =$B6*Inputs!$B$15*Curves!$C$13 -> 15437.832 | M6: =$B6*Inputs!$B$15*Curves!$C$14 -> 17939.444 | N6: =$B6*Inputs!$B$15*Curves!$C$15 -> 12500 | O6: =$B6*Inputs!$B$15*Curves!$C$16 -> 12500 | P6: =$B6*Inputs!$B$15*Curves!$C$17 -> 12500 | Q6: =$B6*Inputs!$B$15*Curves!$C$18 -> 3125 | R6: =$B6*Inputs!$B$15*Curves!$C$19 -> 3125 | S6: =$B6*Inputs!$B$15*Curves!$C$20 -> 3125 | T6: =$B6*Inputs!$B$15*Curves!$C$21 -> 3125 | U6: =$B6*Inputs!$B$15*Curves!$C$22 -> 3125 | V6: =$B6*Inputs!$B$15*Curves!$C$23 -> 3125 | W6: =$B6*Inputs!$B$15*Curves!$C$24 -> 3125 | X6: =$B6*Inputs!$B$15*Curves!$C$25 -> 3125 | Y6: =$B6*Inputs!$B$15*Curves!$C$26 -> 3125 | Z6: =$B6*Inputs!$B$15*Curves!$C$27 -> 3125 | AA6: =$B6*Inputs!$B$15*Curves!$C$28 -> 3125 | AB6: =$B6*Inputs!$B$15*Curves!$C$29 -> 3125 | AC6: =$B6*Inputs!$B$15*Curves!$C$30 -> 3125 | AD6: =$B6*Inputs!$B$15*Curves!$C$31 -> 3125 | AE6: =$B6*Inputs!$B$15*Curves!$C$32 -> 3125 | AF6: =$B6*Inputs!$B$15*Curves!$C$33 -> 3125 | AG6: =$B6*Inputs!$B$15*Curves!$C$34 -> 3125 | AH6: =$B6*Inputs!$B$15*Curves!$C$35 -> 3125 | AI6: =$B6*Inputs!$B$15*Curves!$C$36 -> 3125 | AJ6: =$B6*Inputs!$B$15*Curves!$C$37 -> 3125 | AK6: =$B6*Inputs!$B$15*Curves!$C$38 -> 3125 | AL6: =$B6*Inputs!$B$15*Curves!$C$39 -> 3125
A7: =Acquisition_Plan!A6 -> 2026-04-02 | B7: =Acquisition_Plan!D6+Acquisition_Plan!F6+Acquisition_Plan!E6 -> 300000 | C7: 0 | D7: 0 | E7: =$B7*Inputs!$B$15*Curves!$C$5 -> 236951.25 | F7: =$B7*Inputs!$B$15*Curves!$C$6 -> 112986.47 | G7: =$B7*Inputs!$B$15*Curves!$C$7 -> 72425.497 | H7: =$B7*Inputs!$B$15*Curves!$C$8 -> 50955.68 | I7: =$B7*Inputs!$B$15*Curves!$C$9 -> 30294.671 | J7: =$B7*Inputs!$B$15*Curves!$C$10 -> 27156.92 | K7: =$B7*Inputs!$B$15*Curves!$C$11 -> 23453.925 | L7: =$B7*Inputs!$B$15*Curves!$C$12 -> 20722.852 | M7: =$B7*Inputs!$B$15*Curves!$C$13 -> 18525.399 | N7: =$B7*Inputs!$B$15*Curves!$C$14 -> 21527.333 | O7: =$B7*Inputs!$B$15*Curves!$C$15 -> 15000 | P7: =$B7*Inputs!$B$15*Curves!$C$16 -> 15000 | Q7: =$B7*Inputs!$B$15*Curves!$C$17 -> 15000 | R7: =$B7*Inputs!$B$15*Curves!$C$18 -> 3750 | S7: =$B7*Inputs!$B$15*Curves!$C$19 -> 3750 | T7: =$B7*Inputs!$B$15*Curves!$C$20 -> 3750 | U7: =$B7*Inputs!$B$15*Curves!$C$21 -> 3750 | V7: =$B7*Inputs!$B$15*Curves!$C$22 -> 3750 | W7: =$B7*Inputs!$B$15*Curves!$C$23 -> 3750 | X7: =$B7*Inputs!$B$15*Curves!$C$24 -> 3750 | Y7: =$B7*Inputs!$B$15*Curves!$C$25 -> 3750 | Z7: =$B7*Inputs!$B$15*Curves!$C$26 -> 3750 | AA7: =$B7*Inputs!$B$15*Curves!$C$27 -> 3750 | AB7: =$B7*Inputs!$B$15*Curves!$C$28 -> 3750 | AC7: =$B7*Inputs!$B$15*Curves!$C$29 -> 3750 | AD7: =$B7*Inputs!$B$15*Curves!$C$30 -> 3750 | AE7: =$B7*Inputs!$B$15*Curves!$C$31 -> 3750 | AF7: =$B7*Inputs!$B$15*Curves!$C$32 -> 3750 | AG7: =$B7*Inputs!$B$15*Curves!$C$33 -> 3750 | AH7: =$B7*Inputs!$B$15*Curves!$C$34 -> 3750 | AI7: =$B7*Inputs!$B$15*Curves!$C$35 -> 3750 | AJ7: =$B7*Inputs!$B$15*Curves!$C$36 -> 3750 | AK7: =$B7*Inputs!$B$15*Curves!$C$37 -> 3750 | AL7: =$B7*Inputs!$B$15*Curves!$C$38 -> 3750
A8: =Acquisition_Plan!A7 -> 2026-05-02 | B8: =Acquisition_Plan!D7+Acquisition_Plan!F7+Acquisition_Plan!E7 -> 300000 | C8: 0 | D8: 0 | E8: 0 | F8: =$B8*Inputs!$B$15*Curves!$C$5 -> 236951.25 | G8: =$B8*Inputs!$B$15*Curves!$C$6 -> 112986.47 | H8: =$B8*Inputs!$B$15*Curves!$C$7 -> 72425.497 | I8: =$B8*Inputs!$B$15*Curves!$C$8 -> 50955.68 | J8: =$B8*Inputs!$B$15*Curves!$C$9 -> 30294.671 | K8: =$B8*Inputs!$B$15*Curves!$C$10 -> 27156.92 | L8: =$B8*Inputs!$B$15*Curves!$C$11 -> 23453.925 | M8: =$B8*Inputs!$B$15*Curves!$C$12 -> 20722.852 | N8: =$B8*Inputs!$B$15*Curves!$C$13 -> 18525.399 | O8: =$B8*Inputs!$B$15*Curves!$C$14 -> 21527.333 | P8: =$B8*Inputs!$B$15*Curves!$C$15 -> 15000 | Q8: =$B8*Inputs!$B$15*Curves!$C$16 -> 15000 | R8: =$B8*Inputs!$B$15*Curves!$C$17 -> 15000 | S8: =$B8*Inputs!$B$15*Curves!$C$18 -> 3750 | T8: =$B8*Inputs!$B$15*Curves!$C$19 -> 3750 | U8: =$B8*Inputs!$B$15*Curves!$C$20 -> 3750 | V8: =$B8*Inputs!$B$15*Curves!$C$21 -> 3750 | W8: =$B8*Inputs!$B$15*Curves!$C$22 -> 3750 | X8: =$B8*Inputs!$B$15*Curves!$C$23 -> 3750 | Y8: =$B8*Inputs!$B$15*Curves!$C$24 -> 3750 | Z8: =$B8*Inputs!$B$15*Curves!$C$25 -> 3750 | AA8: =$B8*Inputs!$B$15*Curves!$C$26 -> 3750 | AB8: =$B8*Inputs!$B$15*Curves!$C$27 -> 3750 | AC8: =$B8*Inputs!$B$15*Curves!$C$28 -> 3750 | AD8: =$B8*Inputs!$B$15*Curves!$C$29 -> 3750 | AE8: =$B8*Inputs!$B$15*Curves!$C$30 -> 3750 | AF8: =$B8*Inputs!$B$15*Curves!$C$31 -> 3750 | AG8: =$B8*Inputs!$B$15*Curves!$C$32 -> 3750 | AH8: =$B8*Inputs!$B$15*Curves!$C$33 -> 3750 | AI8: =$B8*Inputs!$B$15*Curves!$C$34 -> 3750 | AJ8: =$B8*Inputs!$B$15*Curves!$C$35 -> 3750 | AK8: =$B8*Inputs!$B$15*Curves!$C$36 -> 3750 | AL8: =$B8*Inputs!$B$15*Curves!$C$37 -> 3750
A9: =Acquisition_Plan!A8 -> 2026-06-01 | B9: =Acquisition_Plan!D8+Acquisition_Plan!F8+Acquisition_Plan!E8 -> 400000 | C9: 0 | D9: 0 | E9: 0 | F9: 0 | G9: =$B9*Inputs!$B$15*Curves!$C$5 -> 315935 | H9: =$B9*Inputs!$B$15*Curves!$C$6 -> 150648.63 | I9: =$B9*Inputs!$B$15*Curves!$C$7 -> 96567.329 | J9: =$B9*Inputs!$B$15*Curves!$C$8 -> 67940.906 | K9: =$B9*Inputs!$B$15*Curves!$C$9 -> 40392.894 | L9: =$B9*Inputs!$B$15*Curves!$C$10 -> 36209.227 | M9: =$B9*Inputs!$B$15*Curves!$C$11 -> 31271.9 | N9: =$B9*Inputs!$B$15*Curves!$C$12 -> 27630.47 | O9: =$B9*Inputs!$B$15*Curves!$C$13 -> 24700.532 | P9: =$B9*Inputs!$B$15*Curves!$C$14 -> 28703.111 | Q9: =$B9*Inputs!$B$15*Curves!$C$15 -> 20000 | R9: =$B9*Inputs!$B$15*Curves!$C$16 -> 20000 | S9: =$B9*Inputs!$B$15*Curves!$C$17 -> 20000 | T9: =$B9*Inputs!$B$15*Curves!$C$18 -> 5000 | U9: =$B9*Inputs!$B$15*Curves!$C$19 -> 5000 | V9: =$B9*Inputs!$B$15*Curves!$C$20 -> 5000 | W9: =$B9*Inputs!$B$15*Curves!$C$21 -> 5000 | X9: =$B9*Inputs!$B$15*Curves!$C$22 -> 5000 | Y9: =$B9*Inputs!$B$15*Curves!$C$23 -> 5000 | Z9: =$B9*Inputs!$B$15*Curves!$C$24 -> 5000 | AA9: =$B9*Inputs!$B$15*Curves!$C$25 -> 5000 | AB9: =$B9*Inputs!$B$15*Curves!$C$26 -> 5000 | AC9: =$B9*Inputs!$B$15*Curves!$C$27 -> 5000 | AD9: =$B9*Inputs!$B$15*Curves!$C$28 -> 5000 | AE9: =$B9*Inputs!$B$15*Curves!$C$29 -> 5000 | AF9: =$B9*Inputs!$B$15*Curves!$C$30 -> 5000 | AG9: =$B9*Inputs!$B$15*Curves!$C$31 -> 5000 | AH9: =$B9*Inputs!$B$15*Curves!$C$32 -> 5000 | AI9: =$B9*Inputs!$B$15*Curves!$C$33 -> 5000 | AJ9: =$B9*Inputs!$B$15*Curves!$C$34 -> 5000 | AK9: =$B9*Inputs!$B$15*Curves!$C$35 -> 5000 | AL9: =$B9*Inputs!$B$15*Curves!$C$36 -> 5000
A10: =Acquisition_Plan!A9 -> 2026-07-01 | B10: =Acquisition_Plan!D9+Acquisition_Plan!F9+Acquisition_Plan!E9 -> 400000 | C10: 0 | D10: 0 | E10: 0 | F10: 0 | G10: 0 | H10: =$B10*Inputs!$B$15*Curves!$C$5 -> 315935 | I10: =$B10*Inputs!$B$15*Curves!$C$6 -> 150648.63 | J10: =$B10*Inputs!$B$15*Curves!$C$7 -> 96567.329 | K10: =$B10*Inputs!$B$15*Curves!$C$8 -> 67940.906 | L10: =$B10*Inputs!$B$15*Curves!$C$9 -> 40392.894 | M10: =$B10*Inputs!$B$15*Curves!$C$10 -> 36209.227 | N10: =$B10*Inputs!$B$15*Curves!$C$11 -> 31271.9 | O10: =$B10*Inputs!$B$15*Curves!$C$12 -> 27630.47 | P10: =$B10*Inputs!$B$15*Curves!$C$13 -> 24700.532 | Q10: =$B10*Inputs!$B$15*Curves!$C$14 -> 28703.111 | R10: =$B10*Inputs!$B$15*Curves!$C$15 -> 20000 | S10: =$B10*Inputs!$B$15*Curves!$C$16 -> 20000 | T10: =$B10*Inputs!$B$15*Curves!$C$17 -> 20000 | U10: =$B10*Inputs!$B$15*Curves!$C$18 -> 5000 | V10: =$B10*Inputs!$B$15*Curves!$C$19 -> 5000 | W10: =$B10*Inputs!$B$15*Curves!$C$20 -> 5000 | X10: =$B10*Inputs!$B$15*Curves!$C$21 -> 5000 | Y10: =$B10*Inputs!$B$15*Curves!$C$22 -> 5000 | Z10: =$B10*Inputs!$B$15*Curves!$C$23 -> 5000 | AA10: =$B10*Inputs!$B$15*Curves!$C$24 -> 5000 | AB10: =$B10*Inputs!$B$15*Curves!$C$25 -> 5000 | AC10: =$B10*Inputs!$B$15*Curves!$C$26 -> 5000 | AD10: =$B10*Inputs!$B$15*Curves!$C$27 -> 5000 | AE10: =$B10*Inputs!$B$15*Curves!$C$28 -> 5000 | AF10: =$B10*Inputs!$B$15*Curves!$C$29 -> 5000 | AG10: =$B10*Inputs!$B$15*Curves!$C$30 -> 5000 | AH10: =$B10*Inputs!$B$15*Curves!$C$31 -> 5000 | AI10: =$B10*Inputs!$B$15*Curves!$C$32 -> 5000 | AJ10: =$B10*Inputs!$B$15*Curves!$C$33 -> 5000 | AK10: =$B10*Inputs!$B$15*Curves!$C$34 -> 5000 | AL10: =$B10*Inputs!$B$15*Curves!$C$35 -> 5000
A11: =Acquisition_Plan!A10 -> 2026-07-31 | B11: =Acquisition_Plan!D10+Acquisition_Plan!F10+Acquisition_Plan!E10 -> 500000 | C11: 0 | D11: 0 | E11: 0 | F11: 0 | G11: 0 | H11: 0 | I11: =$B11*Inputs!$B$15*Curves!$C$5 -> 394918.75 | J11: =$B11*Inputs!$B$15*Curves!$C$6 -> 188310.79 | K11: =$B11*Inputs!$B$15*Curves!$C$7 -> 120709.16 | L11: =$B11*Inputs!$B$15*Curves!$C$8 -> 84926.133 | M11: =$B11*Inputs!$B$15*Curves!$C$9 -> 50491.118 | N11: =$B11*Inputs!$B$15*Curves!$C$10 -> 45261.534 | O11: =$B11*Inputs!$B$15*Curves!$C$11 -> 39089.875 | P11: =$B11*Inputs!$B$15*Curves!$C$12 -> 34538.087 | Q11: =$B11*Inputs!$B$15*Curves!$C$13 -> 30875.665 | R11: =$B11*Inputs!$B$15*Curves!$C$14 -> 35878.889 | S11: =$B11*Inputs!$B$15*Curves!$C$15 -> 25000 | T11: =$B11*Inputs!$B$15*Curves!$C$16 -> 25000 | U11: =$B11*Inputs!$B$15*Curves!$C$17 -> 25000 | V11: =$B11*Inputs!$B$15*Curves!$C$18 -> 6250 | W11: =$B11*Inputs!$B$15*Curves!$C$19 -> 6250 | X11: =$B11*Inputs!$B$15*Curves!$C$20 -> 6250 | Y11: =$B11*Inputs!$B$15*Curves!$C$21 -> 6250 | Z11: =$B11*Inputs!$B$15*Curves!$C$22 -> 6250 | AA11: =$B11*Inputs!$B$15*Curves!$C$23 -> 6250 | AB11: =$B11*Inputs!$B$15*Curves!$C$24 -> 6250 | AC11: =$B11*Inputs!$B$15*Curves!$C$25 -> 6250 | AD11: =$B11*Inputs!$B$15*Curves!$C$26 -> 6250 | AE11: =$B11*Inputs!$B$15*Curves!$C$27 -> 6250 | AF11: =$B11*Inputs!$B$15*Curves!$C$28 -> 6250 | AG11: =$B11*Inputs!$B$15*Curves!$C$29 -> 6250 | AH11: =$B11*Inputs!$B$15*Curves!$C$30 -> 6250 | AI11: =$B11*Inputs!$B$15*Curves!$C$31 -> 6250 | AJ11: =$B11*Inputs!$B$15*Curves!$C$32 -> 6250 | AK11: =$B11*Inputs!$B$15*Curves!$C$33 -> 6250 | AL11: =$B11*Inputs!$B$15*Curves!$C$34 -> 6250
A12: =Acquisition_Plan!A11 -> 2026-08-30 | B12: =Acquisition_Plan!D11+Acquisition_Plan!F11+Acquisition_Plan!E11 -> 500000 | C12: 0 | D12: 0 | E12: 0 | F12: 0 | G12: 0 | H12: 0 | I12: 0 | J12: =$B12*Inputs!$B$15*Curves!$C$5 -> 394918.75 | K12: =$B12*Inputs!$B$15*Curves!$C$6 -> 188310.79 | L12: =$B12*Inputs!$B$15*Curves!$C$7 -> 120709.16 | M12: =$B12*Inputs!$B$15*Curves!$C$8 -> 84926.133 | N12: =$B12*Inputs!$B$15*Curves!$C$9 -> 50491.118 | O12: =$B12*Inputs!$B$15*Curves!$C$10 -> 45261.534 | P12: =$B12*Inputs!$B$15*Curves!$C$11 -> 39089.875 | Q12: =$B12*Inputs!$B$15*Curves!$C$12 -> 34538.087 | R12: =$B12*Inputs!$B$15*Curves!$C$13 -> 30875.665 | S12: =$B12*Inputs!$B$15*Curves!$C$14 -> 35878.889 | T12: =$B12*Inputs!$B$15*Curves!$C$15 -> 25000 | U12: =$B12*Inputs!$B$15*Curves!$C$16 -> 25000 | V12: =$B12*Inputs!$B$15*Curves!$C$17 -> 25000 | W12: =$B12*Inputs!$B$15*Curves!$C$18 -> 6250 | X12: =$B12*Inputs!$B$15*Curves!$C$19 -> 6250 | Y12: =$B12*Inputs!$B$15*Curves!$C$20 -> 6250 | Z12: =$B12*Inputs!$B$15*Curves!$C$21 -> 6250 | AA12: =$B12*Inputs!$B$15*Curves!$C$22 -> 6250 | AB12: =$B12*Inputs!$B$15*Curves!$C$23 -> 6250 | AC12: =$B12*Inputs!$B$15*Curves!$C$24 -> 6250 | AD12: =$B12*Inputs!$B$15*Curves!$C$25 -> 6250 | AE12: =$B12*Inputs!$B$15*Curves!$C$26 -> 6250 | AF12: =$B12*Inputs!$B$15*Curves!$C$27 -> 6250 | AG12: =$B12*Inputs!$B$15*Curves!$C$28 -> 6250 | AH12: =$B12*Inputs!$B$15*Curves!$C$29 -> 6250 | AI12: =$B12*Inputs!$B$15*Curves!$C$30 -> 6250 | AJ12: =$B12*Inputs!$B$15*Curves!$C$31 -> 6250 | AK12: =$B12*Inputs!$B$15*Curves!$C$32 -> 6250 | AL12: =$B12*Inputs!$B$15*Curves!$C$33 -> 6250
A13: =Acquisition_Plan!A12 -> 2026-09-29 | B13: =Acquisition_Plan!D12+Acquisition_Plan!F12+Acquisition_Plan!E12 -> 600000 | C13: 0 | D13: 0 | E13: 0 | F13: 0 | G13: 0 | H13: 0 | I13: 0 | J13: 0 | K13: =$B13*Inputs!$B$15*Curves!$C$5 -> 473902.5 | L13: =$B13*Inputs!$B$15*Curves!$C$6 -> 225972.95 | M13: =$B13*Inputs!$B$15*Curves!$C$7 -> 144850.99 | N13: =$B13*Inputs!$B$15*Curves!$C$8 -> 101911.36 | O13: =$B13*Inputs!$B$15*Curves!$C$9 -> 60589.342 | P13: =$B13*Inputs!$B$15*Curves!$C$10 -> 54313.84 | Q13: =$B13*Inputs!$B$15*Curves!$C$11 -> 46907.85 | R13: =$B13*Inputs!$B$15*Curves!$C$12 -> 41445.705 | S13: =$B13*Inputs!$B$15*Curves!$C$13 -> 37050.798 | T13: =$B13*Inputs!$B$15*Curves!$C$14 -> 43054.666 | U13: =$B13*Inputs!$B$15*Curves!$C$15 -> 30000 | V13: =$B13*Inputs!$B$15*Curves!$C$16 -> 30000 | W13: =$B13*Inputs!$B$15*Curves!$C$17 -> 30000 | X13: =$B13*Inputs!$B$15*Curves!$C$18 -> 7500 | Y13: =$B13*Inputs!$B$15*Curves!$C$19 -> 7500 | Z13: =$B13*Inputs!$B$15*Curves!$C$20 -> 7500 | AA13: =$B13*Inputs!$B$15*Curves!$C$21 -> 7500 | AB13: =$B13*Inputs!$B$15*Curves!$C$22 -> 7500 | AC13: =$B13*Inputs!$B$15*Curves!$C$23 -> 7500 | AD13: =$B13*Inputs!$B$15*Curves!$C$24 -> 7500 | AE13: =$B13*Inputs!$B$15*Curves!$C$25 -> 7500 | AF13: =$B13*Inputs!$B$15*Curves!$C$26 -> 7500 | AG13: =$B13*Inputs!$B$15*Curves!$C$27 -> 7500 | AH13: =$B13*Inputs!$B$15*Curves!$C$28 -> 7500 | AI13: =$B13*Inputs!$B$15*Curves!$C$29 -> 7500 | AJ13: =$B13*Inputs!$B$15*Curves!$C$30 -> 7500 | AK13: =$B13*Inputs!$B$15*Curves!$C$31 -> 7500 | AL13: =$B13*Inputs!$B$15*Curves!$C$32 -> 7500
A14: =Acquisition_Plan!A13 -> 2026-10-29 | B14: =Acquisition_Plan!D13+Acquisition_Plan!F13+Acquisition_Plan!E13 -> 600000 | C14: 0 | D14: 0 | E14: 0 | F14: 0 | G14: 0 | H14: 0 | I14: 0 | J14: 0 | K14: 0 | L14: =$B14*Inputs!$B$15*Curves!$C$5 -> 473902.5 | M14: =$B14*Inputs!$B$15*Curves!$C$6 -> 225972.95 | N14: =$B14*Inputs!$B$15*Curves!$C$7 -> 144850.99 | O14: =$B14*Inputs!$B$15*Curves!$C$8 -> 101911.36 | P14: =$B14*Inputs!$B$15*Curves!$C$9 -> 60589.342 | Q14: =$B14*Inputs!$B$15*Curves!$C$10 -> 54313.84 | R14: =$B14*Inputs!$B$15*Curves!$C$11 -> 46907.85 | S14: =$B14*Inputs!$B$15*Curves!$C$12 -> 41445.705 | T14: =$B14*Inputs!$B$15*Curves!$C$13 -> 37050.798 | U14: =$B14*Inputs!$B$15*Curves!$C$14 -> 43054.666 | V14: =$B14*Inputs!$B$15*Curves!$C$15 -> 30000 | W14: =$B14*Inputs!$B$15*Curves!$C$16 -> 30000 | X14: =$B14*Inputs!$B$15*Curves!$C$17 -> 30000 | Y14: =$B14*Inputs!$B$15*Curves!$C$18 -> 7500 | Z14: =$B14*Inputs!$B$15*Curves!$C$19 -> 7500 | AA14: =$B14*Inputs!$B$15*Curves!$C$20 -> 7500 | AB14: =$B14*Inputs!$B$15*Curves!$C$21 -> 7500 | AC14: =$B14*Inputs!$B$15*Curves!$C$22 -> 7500 | AD14: =$B14*Inputs!$B$15*Curves!$C$23 -> 7500 | AE14: =$B14*Inputs!$B$15*Curves!$C$24 -> 7500 | AF14: =$B14*Inputs!$B$15*Curves!$C$25 -> 7500 | AG14: =$B14*Inputs!$B$15*Curves!$C$26 -> 7500 | AH14: =$B14*Inputs!$B$15*Curves!$C$27 -> 7500 | AI14: =$B14*Inputs!$B$15*Curves!$C$28 -> 7500 | AJ14: =$B14*Inputs!$B$15*Curves!$C$29 -> 7500 | AK14: =$B14*Inputs!$B$15*Curves!$C$30 -> 7500 | AL14: =$B14*Inputs!$B$15*Curves!$C$31 -> 7500
A15: =Acquisition_Plan!A14 -> 2026-11-28 | B15: =Acquisition_Plan!D14+Acquisition_Plan!F14+Acquisition_Plan!E14 -> 700000 | C15: 0 | D15: 0 | E15: 0 | F15: 0 | G15: 0 | H15: 0 | I15: 0 | J15: 0 | K15: 0 | L15: 0 | M15: =$B15*Inputs!$B$15*Curves!$C$5 -> 552886.25 | N15: =$B15*Inputs!$B$15*Curves!$C$6 -> 263635.1 | O15: =$B15*Inputs!$B$15*Curves!$C$7 -> 168992.83 | P15: =$B15*Inputs!$B$15*Curves!$C$8 -> 118896.59 | Q15: =$B15*Inputs!$B$15*Curves!$C$9 -> 70687.565 | R15: =$B15*Inputs!$B$15*Curves!$C$10 -> 63366.147 | S15: =$B15*Inputs!$B$15*Curves!$C$11 -> 54725.825 | T15: =$B15*Inputs!$B$15*Curves!$C$12 -> 48353.322 | U15: =$B15*Inputs!$B$15*Curves!$C$13 -> 43225.93 | V15: =$B15*Inputs!$B$15*Curves!$C$14 -> 50230.444 | W15: =$B15*Inputs!$B$15*Curves!$C$15 -> 35000 | X15: =$B15*Inputs!$B$15*Curves!$C$16 -> 35000 | Y15: =$B15*Inputs!$B$15*Curves!$C$17 -> 35000 | Z15: =$B15*Inputs!$B$15*Curves!$C$18 -> 8750 | AA15: =$B15*Inputs!$B$15*Curves!$C$19 -> 8750 | AB15: =$B15*Inputs!$B$15*Curves!$C$20 -> 8750 | AC15: =$B15*Inputs!$B$15*Curves!$C$21 -> 8750 | AD15: =$B15*Inputs!$B$15*Curves!$C$22 -> 8750 | AE15: =$B15*Inputs!$B$15*Curves!$C$23 -> 8750 | AF15: =$B15*Inputs!$B$15*Curves!$C$24 -> 8750 | AG15: =$B15*Inputs!$B$15*Curves!$C$25 -> 8750 | AH15: =$B15*Inputs!$B$15*Curves!$C$26 -> 8750 | AI15: =$B15*Inputs!$B$15*Curves!$C$27 -> 8750 | AJ15: =$B15*Inputs!$B$15*Curves!$C$28 -> 8750 | AK15: =$B15*Inputs!$B$15*Curves!$C$29 -> 8750 | AL15: =$B15*Inputs!$B$15*Curves!$C$30 -> 8750
A16: =Acquisition_Plan!A15 -> 2026-12-28 | B16: =Acquisition_Plan!D15+Acquisition_Plan!F15+Acquisition_Plan!E15 -> 700000 | C16: 0 | D16: 0 | E16: 0 | F16: 0 | G16: 0 | H16: 0 | I16: 0 | J16: 0 | K16: 0 | L16: 0 | M16: 0 | N16: =$B16*Inputs!$B$15*Curves!$C$5 -> 552886.25 | O16: =$B16*Inputs!$B$15*Curves!$C$6 -> 263635.1 | P16: =$B16*Inputs!$B$15*Curves!$C$7 -> 168992.83 | Q16: =$B16*Inputs!$B$15*Curves!$C$8 -> 118896.59 | R16: =$B16*Inputs!$B$15*Curves!$C$9 -> 70687.565 | S16: =$B16*Inputs!$B$15*Curves!$C$10 -> 63366.147 | T16: =$B16*Inputs!$B$15*Curves!$C$11 -> 54725.825 | U16: =$B16*Inputs!$B$15*Curves!$C$12 -> 48353.322 | V16: =$B16*Inputs!$B$15*Curves!$C$13 -> 43225.93 | W16: =$B16*Inputs!$B$15*Curves!$C$14 -> 50230.444 | X16: =$B16*Inputs!$B$15*Curves!$C$15 -> 35000 | Y16: =$B16*Inputs!$B$15*Curves!$C$16 -> 35000 | Z16: =$B16*Inputs!$B$15*Curves!$C$17 -> 35000 | AA16: =$B16*Inputs!$B$15*Curves!$C$18 -> 8750 | AB16: =$B16*Inputs!$B$15*Curves!$C$19 -> 8750 | AC16: =$B16*Inputs!$B$15*Curves!$C$20 -> 8750 | AD16: =$B16*Inputs!$B$15*Curves!$C$21 -> 8750 | AE16: =$B16*Inputs!$B$15*Curves!$C$22 -> 8750 | AF16: =$B16*Inputs!$B$15*Curves!$C$23 -> 8750 | AG16: =$B16*Inputs!$B$15*Curves!$C$24 -> 8750 | AH16: =$B16*Inputs!$B$15*Curves!$C$25 -> 8750 | AI16: =$B16*Inputs!$B$15*Curves!$C$26 -> 8750 | AJ16: =$B16*Inputs!$B$15*Curves!$C$27 -> 8750 | AK16: =$B16*Inputs!$B$15*Curves!$C$28 -> 8750 | AL16: =$B16*Inputs!$B$15*Curves!$C$29 -> 8750
A17: =Acquisition_Plan!A16 -> 2027-01-27 | B17: =Acquisition_Plan!D16+Acquisition_Plan!F16+Acquisition_Plan!E16 -> 800000 | C17: 0 | D17: 0 | E17: 0 | F17: 0 | G17: 0 | H17: 0 | I17: 0 | J17: 0 | K17: 0 | L17: 0 | M17: 0 | N17: 0 | O17: =$B17*Inputs!$B$15*Curves!$C$5 -> 631870 | P17: =$B17*Inputs!$B$15*Curves!$C$6 -> 301297.26 | Q17: =$B17*Inputs!$B$15*Curves!$C$7 -> 193134.66 | R17: =$B17*Inputs!$B$15*Curves!$C$8 -> 135881.81 | S17: =$B17*Inputs!$B$15*Curves!$C$9 -> 80785.789 | T17: =$B17*Inputs!$B$15*Curves!$C$10 -> 72418.454 | U17: =$B17*Inputs!$B$15*Curves!$C$11 -> 62543.8 | V17: =$B17*Inputs!$B$15*Curves!$C$12 -> 55260.94 | W17: =$B17*Inputs!$B$15*Curves!$C$13 -> 49401.063 | X17: =$B17*Inputs!$B$15*Curves!$C$14 -> 57406.222 | Y17: =$B17*Inputs!$B$15*Curves!$C$15 -> 40000 | Z17: =$B17*Inputs!$B$15*Curves!$C$16 -> 40000 | AA17: =$B17*Inputs!$B$15*Curves!$C$17 -> 40000 | AB17: =$B17*Inputs!$B$15*Curves!$C$18 -> 10000 | AC17: =$B17*Inputs!$B$15*Curves!$C$19 -> 10000 | AD17: =$B17*Inputs!$B$15*Curves!$C$20 -> 10000 | AE17: =$B17*Inputs!$B$15*Curves!$C$21 -> 10000 | AF17: =$B17*Inputs!$B$15*Curves!$C$22 -> 10000 | AG17: =$B17*Inputs!$B$15*Curves!$C$23 -> 10000 | AH17: =$B17*Inputs!$B$15*Curves!$C$24 -> 10000 | AI17: =$B17*Inputs!$B$15*Curves!$C$25 -> 10000 | AJ17: =$B17*Inputs!$B$15*Curves!$C$26 -> 10000 | AK17: =$B17*Inputs!$B$15*Curves!$C$27 -> 10000 | AL17: =$B17*Inputs!$B$15*Curves!$C$28 -> 10000
A18: =Acquisition_Plan!A17 -> 2027-02-26 | B18: =Acquisition_Plan!D17+Acquisition_Plan!F17+Acquisition_Plan!E17 -> 800000 | C18: 0 | D18: 0 | E18: 0 | F18: 0 | G18: 0 | H18: 0 | I18: 0 | J18: 0 | K18: 0 | L18: 0 | M18: 0 | N18: 0 | O18: 0 | P18: =$B18*Inputs!$B$15*Curves!$C$5 -> 631870 | Q18: =$B18*Inputs!$B$15*Curves!$C$6 -> 301297.26 | R18: =$B18*Inputs!$B$15*Curves!$C$7 -> 193134.66 | S18: =$B18*Inputs!$B$15*Curves!$C$8 -> 135881.81 | T18: =$B18*Inputs!$B$15*Curves!$C$9 -> 80785.789 | U18: =$B18*Inputs!$B$15*Curves!$C$10 -> 72418.454 | V18: =$B18*Inputs!$B$15*Curves!$C$11 -> 62543.8 | W18: =$B18*Inputs!$B$15*Curves!$C$12 -> 55260.94 | X18: =$B18*Inputs!$B$15*Curves!$C$13 -> 49401.063 | Y18: =$B18*Inputs!$B$15*Curves!$C$14 -> 57406.222 | Z18: =$B18*Inputs!$B$15*Curves!$C$15 -> 40000 | AA18: =$B18*Inputs!$B$15*Curves!$C$16 -> 40000 | AB18: =$B18*Inputs!$B$15*Curves!$C$17 -> 40000 | AC18: =$B18*Inputs!$B$15*Curves!$C$18 -> 10000 | AD18: =$B18*Inputs!$B$15*Curves!$C$19 -> 10000 | AE18: =$B18*Inputs!$B$15*Curves!$C$20 -> 10000 | AF18: =$B18*Inputs!$B$15*Curves!$C$21 -> 10000 | AG18: =$B18*Inputs!$B$15*Curves!$C$22 -> 10000 | AH18: =$B18*Inputs!$B$15*Curves!$C$23 -> 10000 | AI18: =$B18*Inputs!$B$15*Curves!$C$24 -> 10000 | AJ18: =$B18*Inputs!$B$15*Curves!$C$25 -> 10000 | AK18: =$B18*Inputs!$B$15*Curves!$C$26 -> 10000 | AL18: =$B18*Inputs!$B$15*Curves!$C$27 -> 10000
A19: =Acquisition_Plan!A18 -> 2027-03-28 | B19: =Acquisition_Plan!D18+Acquisition_Plan!F18+Acquisition_Plan!E18 -> 800000 | C19: 0 | D19: 0 | E19: 0 | F19: 0 | G19: 0 | H19: 0 | I19: 0 | J19: 0 | K19: 0 | L19: 0 | M19: 0 | N19: 0 | O19: 0 | P19: 0 | Q19: =$B19*Inputs!$B$15*Curves!$C$5 -> 631870 | R19: =$B19*Inputs!$B$15*Curves!$C$6 -> 301297.26 | S19: =$B19*Inputs!$B$15*Curves!$C$7 -> 193134.66 | T19: =$B19*Inputs!$B$15*Curves!$C$8 -> 135881.81 | U19: =$B19*Inputs!$B$15*Curves!$C$9 -> 80785.789 | V19: =$B19*Inputs!$B$15*Curves!$C$10 -> 72418.454 | W19: =$B19*Inputs!$B$15*Curves!$C$11 -> 62543.8 | X19: =$B19*Inputs!$B$15*Curves!$C$12 -> 55260.94 | Y19: =$B19*Inputs!$B$15*Curves!$C$13 -> 49401.063 | Z19: =$B19*Inputs!$B$15*Curves!$C$14 -> 57406.222 | AA19: =$B19*Inputs!$B$15*Curves!$C$15 -> 40000 | AB19: =$B19*Inputs!$B$15*Curves!$C$16 -> 40000 | AC19: =$B19*Inputs!$B$15*Curves!$C$17 -> 40000 | AD19: =$B19*Inputs!$B$15*Curves!$C$18 -> 10000 | AE19: =$B19*Inputs!$B$15*Curves!$C$19 -> 10000 | AF19: =$B19*Inputs!$B$15*Curves!$C$20 -> 10000 | AG19: =$B19*Inputs!$B$15*Curves!$C$21 -> 10000 | AH19: =$B19*Inputs!$B$15*Curves!$C$22 -> 10000 | AI19: =$B19*Inputs!$B$15*Curves!$C$23 -> 10000 | AJ19: =$B19*Inputs!$B$15*Curves!$C$24 -> 10000 | AK19: =$B19*Inputs!$B$15*Curves!$C$25 -> 10000 | AL19: =$B19*Inputs!$B$15*Curves!$C$26 -> 10000
A20: =Acquisition_Plan!A19 -> 2027-04-27 | B20: =Acquisition_Plan!D19+Acquisition_Plan!F19+Acquisition_Plan!E19 -> 800000 | C20: 0 | D20: 0 | E20: 0 | F20: 0 | G20: 0 | H20: 0 | I20: 0 | J20: 0 | K20: 0 | L20: 0 | M20: 0 | N20: 0 | O20: 0 | P20: 0 | Q20: 0 | R20: =$B20*Inputs!$B$15*Curves!$C$5 -> 631870 | S20: =$B20*Inputs!$B$15*Curves!$C$6 -> 301297.26 | T20: =$B20*Inputs!$B$15*Curves!$C$7 -> 193134.66 | U20: =$B20*Inputs!$B$15*Curves!$C$8 -> 135881.81 | V20: =$B20*Inputs!$B$15*Curves!$C$9 -> 80785.789 | W20: =$B20*Inputs!$B$15*Curves!$C$10 -> 72418.454 | X20: =$B20*Inputs!$B$15*Curves!$C$11 -> 62543.8 | Y20: =$B20*Inputs!$B$15*Curves!$C$12 -> 55260.94 | Z20: =$B20*Inputs!$B$15*Curves!$C$13 -> 49401.063 | AA20: =$B20*Inputs!$B$15*Curves!$C$14 -> 57406.222 | AB20: =$B20*Inputs!$B$15*Curves!$C$15 -> 40000 | AC20: =$B20*Inputs!$B$15*Curves!$C$16 -> 40000 | AD20: =$B20*Inputs!$B$15*Curves!$C$17 -> 40000 | AE20: =$B20*Inputs!$B$15*Curves!$C$18 -> 10000 | AF20: =$B20*Inputs!$B$15*Curves!$C$19 -> 10000 | AG20: =$B20*Inputs!$B$15*Curves!$C$20 -> 10000 | AH20: =$B20*Inputs!$B$15*Curves!$C$21 -> 10000 | AI20: =$B20*Inputs!$B$15*Curves!$C$22 -> 10000 | AJ20: =$B20*Inputs!$B$15*Curves!$C$23 -> 10000 | AK20: =$B20*Inputs!$B$15*Curves!$C$24 -> 10000 | AL20: =$B20*Inputs!$B$15*Curves!$C$25 -> 10000
A21: =Acquisition_Plan!A20 -> 2027-05-27 | B21: =Acquisition_Plan!D20+Acquisition_Plan!F20+Acquisition_Plan!E20 -> 800000 | C21: 0 | D21: 0 | E21: 0 | F21: 0 | G21: 0 | H21: 0 | I21: 0 | J21: 0 | K21: 0 | L21: 0 | M21: 0 | N21: 0 | O21: 0 | P21: 0 | Q21: 0 | R21: 0 | S21: =$B21*Inputs!$B$15*Curves!$C$5 -> 631870 | T21: =$B21*Inputs!$B$15*Curves!$C$6 -> 301297.26 | U21: =$B21*Inputs!$B$15*Curves!$C$7 -> 193134.66 | V21: =$B21*Inputs!$B$15*Curves!$C$8 -> 135881.81 | W21: =$B21*Inputs!$B$15*Curves!$C$9 -> 80785.789 | X21: =$B21*Inputs!$B$15*Curves!$C$10 -> 72418.454 | Y21: =$B21*Inputs!$B$15*Curves!$C$11 -> 62543.8 | Z21: =$B21*Inputs!$B$15*Curves!$C$12 -> 55260.94 | AA21: =$B21*Inputs!$B$15*Curves!$C$13 -> 49401.063 | AB21: =$B21*Inputs!$B$15*Curves!$C$14 -> 57406.222 | AC21: =$B21*Inputs!$B$15*Curves!$C$15 -> 40000 | AD21: =$B21*Inputs!$B$15*Curves!$C$16 -> 40000 | AE21: =$B21*Inputs!$B$15*Curves!$C$17 -> 40000 | AF21: =$B21*Inputs!$B$15*Curves!$C$18 -> 10000 | AG21: =$B21*Inputs!$B$15*Curves!$C$19 -> 10000 | AH21: =$B21*Inputs!$B$15*Curves!$C$20 -> 10000 | AI21: =$B21*Inputs!$B$15*Curves!$C$21 -> 10000 | AJ21: =$B21*Inputs!$B$15*Curves!$C$22 -> 10000 | AK21: =$B21*Inputs!$B$15*Curves!$C$23 -> 10000 | AL21: =$B21*Inputs!$B$15*Curves!$C$24 -> 10000
A22: =Acquisition_Plan!A21 -> 2027-06-26 | B22: =Acquisition_Plan!D21+Acquisition_Plan!F21+Acquisition_Plan!E21 -> 800000 | C22: 0 | D22: 0 | E22: 0 | F22: 0 | G22: 0 | H22: 0 | I22: 0 | J22: 0 | K22: 0 | L22: 0 | M22: 0 | N22: 0 | O22: 0 | P22: 0 | Q22: 0 | R22: 0 | S22: 0 | T22: =$B22*Inputs!$B$15*Curves!$C$5 -> 631870 | U22: =$B22*Inputs!$B$15*Curves!$C$6 -> 301297.26 | V22: =$B22*Inputs!$B$15*Curves!$C$7 -> 193134.66 | W22: =$B22*Inputs!$B$15*Curves!$C$8 -> 135881.81 | X22: =$B22*Inputs!$B$15*Curves!$C$9 -> 80785.789 | Y22: =$B22*Inputs!$B$15*Curves!$C$10 -> 72418.454 | Z22: =$B22*Inputs!$B$15*Curves!$C$11 -> 62543.8 | AA22: =$B22*Inputs!$B$15*Curves!$C$12 -> 55260.94 | AB22: =$B22*Inputs!$B$15*Curves!$C$13 -> 49401.063 | AC22: =$B22*Inputs!$B$15*Curves!$C$14 -> 57406.222 | AD22: =$B22*Inputs!$B$15*Curves!$C$15 -> 40000 | AE22: =$B22*Inputs!$B$15*Curves!$C$16 -> 40000 | AF22: =$B22*Inputs!$B$15*Curves!$C$17 -> 40000 | AG22: =$B22*Inputs!$B$15*Curves!$C$18 -> 10000 | AH22: =$B22*Inputs!$B$15*Curves!$C$19 -> 10000 | AI22: =$B22*Inputs!$B$15*Curves!$C$20 -> 10000 | AJ22: =$B22*Inputs!$B$15*Curves!$C$21 -> 10000 | AK22: =$B22*Inputs!$B$15*Curves!$C$22 -> 10000 | AL22: =$B22*Inputs!$B$15*Curves!$C$23 -> 10000
A23: =Acquisition_Plan!A22 -> 2027-07-26 | B23: =Acquisition_Plan!D22+Acquisition_Plan!F22+Acquisition_Plan!E22 -> 800000 | C23: 0 | D23: 0 | E23: 0 | F23: 0 | G23: 0 | H23: 0 | I23: 0 | J23: 0 | K23: 0 | L23: 0 | M23: 0 | N23: 0 | O23: 0 | P23: 0 | Q23: 0 | R23: 0 | S23: 0 | T23: 0 | U23: =$B23*Inputs!$B$15*Curves!$C$5 -> 631870 | V23: =$B23*Inputs!$B$15*Curves!$C$6 -> 301297.26 | W23: =$B23*Inputs!$B$15*Curves!$C$7 -> 193134.66 | X23: =$B23*Inputs!$B$15*Curves!$C$8 -> 135881.81 | Y23: =$B23*Inputs!$B$15*Curves!$C$9 -> 80785.789 | Z23: =$B23*Inputs!$B$15*Curves!$C$10 -> 72418.454 | AA23: =$B23*Inputs!$B$15*Curves!$C$11 -> 62543.8 | AB23: =$B23*Inputs!$B$15*Curves!$C$12 -> 55260.94 | AC23: =$B23*Inputs!$B$15*Curves!$C$13 -> 49401.063 | AD23: =$B23*Inputs!$B$15*Curves!$C$14 -> 57406.222 | AE23: =$B23*Inputs!$B$15*Curves!$C$15 -> 40000 | AF23: =$B23*Inputs!$B$15*Curves!$C$16 -> 40000 | AG23: =$B23*Inputs!$B$15*Curves!$C$17 -> 40000 | AH23: =$B23*Inputs!$B$15*Curves!$C$18 -> 10000 | AI23: =$B23*Inputs!$B$15*Curves!$C$19 -> 10000 | AJ23: =$B23*Inputs!$B$15*Curves!$C$20 -> 10000 | AK23: =$B23*Inputs!$B$15*Curves!$C$21 -> 10000 | AL23: =$B23*Inputs!$B$15*Curves!$C$22 -> 10000
A24: =Acquisition_Plan!A23 -> 2027-08-25 | B24: =Acquisition_Plan!D23+Acquisition_Plan!F23+Acquisition_Plan!E23 -> 800000 | C24: 0 | D24: 0 | E24: 0 | F24: 0 | G24: 0 | H24: 0 | I24: 0 | J24: 0 | K24: 0 | L24: 0 | M24: 0 | N24: 0 | O24: 0 | P24: 0 | Q24: 0 | R24: 0 | S24: 0 | T24: 0 | U24: 0 | V24: =$B24*Inputs!$B$15*Curves!$C$5 -> 631870 | W24: =$B24*Inputs!$B$15*Curves!$C$6 -> 301297.26 | X24: =$B24*Inputs!$B$15*Curves!$C$7 -> 193134.66 | Y24: =$B24*Inputs!$B$15*Curves!$C$8 -> 135881.81 | Z24: =$B24*Inputs!$B$15*Curves!$C$9 -> 80785.789 | AA24: =$B24*Inputs!$B$15*Curves!$C$10 -> 72418.454 | AB24: =$B24*Inputs!$B$15*Curves!$C$11 -> 62543.8 | AC24: =$B24*Inputs!$B$15*Curves!$C$12 -> 55260.94 | AD24: =$B24*Inputs!$B$15*Curves!$C$13 -> 49401.063 | AE24: =$B24*Inputs!$B$15*Curves!$C$14 -> 57406.222 | AF24: =$B24*Inputs!$B$15*Curves!$C$15 -> 40000 | AG24: =$B24*Inputs!$B$15*Curves!$C$16 -> 40000 | AH24: =$B24*Inputs!$B$15*Curves!$C$17 -> 40000 | AI24: =$B24*Inputs!$B$15*Curves!$C$18 -> 10000 | AJ24: =$B24*Inputs!$B$15*Curves!$C$19 -> 10000 | AK24: =$B24*Inputs!$B$15*Curves!$C$20 -> 10000 | AL24: =$B24*Inputs!$B$15*Curves!$C$21 -> 10000
A25: =Acquisition_Plan!A24 -> 2027-09-24 | B25: =Acquisition_Plan!D24+Acquisition_Plan!F24+Acquisition_Plan!E24 -> 800000 | C25: 0 | D25: 0 | E25: 0 | F25: 0 | G25: 0 | H25: 0 | I25: 0 | J25: 0 | K25: 0 | L25: 0 | M25: 0 | N25: 0 | O25: 0 | P25: 0 | Q25: 0 | R25: 0 | S25: 0 | T25: 0 | U25: 0 | V25: 0 | W25: =$B25*Inputs!$B$15*Curves!$C$5 -> 631870 | X25: =$B25*Inputs!$B$15*Curves!$C$6 -> 301297.26 | Y25: =$B25*Inputs!$B$15*Curves!$C$7 -> 193134.66 | Z25: =$B25*Inputs!$B$15*Curves!$C$8 -> 135881.81 | AA25: =$B25*Inputs!$B$15*Curves!$C$9 -> 80785.789 | AB25: =$B25*Inputs!$B$15*Curves!$C$10 -> 72418.454 | AC25: =$B25*Inputs!$B$15*Curves!$C$11 -> 62543.8 | AD25: =$B25*Inputs!$B$15*Curves!$C$12 -> 55260.94 | AE25: =$B25*Inputs!$B$15*Curves!$C$13 -> 49401.063 | AF25: =$B25*Inputs!$B$15*Curves!$C$14 -> 57406.222 | AG25: =$B25*Inputs!$B$15*Curves!$C$15 -> 40000 | AH25: =$B25*Inputs!$B$15*Curves!$C$16 -> 40000 | AI25: =$B25*Inputs!$B$15*Curves!$C$17 -> 40000 | AJ25: =$B25*Inputs!$B$15*Curves!$C$18 -> 10000 | AK25: =$B25*Inputs!$B$15*Curves!$C$19 -> 10000 | AL25: =$B25*Inputs!$B$15*Curves!$C$20 -> 10000
A26: =Acquisition_Plan!A25 -> 2027-10-24 | B26: =Acquisition_Plan!D25+Acquisition_Plan!F25+Acquisition_Plan!E25 -> 800000 | C26: 0 | D26: 0 | E26: 0 | F26: 0 | G26: 0 | H26: 0 | I26: 0 | J26: 0 | K26: 0 | L26: 0 | M26: 0 | N26: 0 | O26: 0 | P26: 0 | Q26: 0 | R26: 0 | S26: 0 | T26: 0 | U26: 0 | V26: 0 | W26: 0 | X26: =$B26*Inputs!$B$15*Curves!$C$5 -> 631870 | Y26: =$B26*Inputs!$B$15*Curves!$C$6 -> 301297.26 | Z26: =$B26*Inputs!$B$15*Curves!$C$7 -> 193134.66 | AA26: =$B26*Inputs!$B$15*Curves!$C$8 -> 135881.81 | AB26: =$B26*Inputs!$B$15*Curves!$C$9 -> 80785.789 | AC26: =$B26*Inputs!$B$15*Curves!$C$10 -> 72418.454 | AD26: =$B26*Inputs!$B$15*Curves!$C$11 -> 62543.8 | AE26: =$B26*Inputs!$B$15*Curves!$C$12 -> 55260.94 | AF26: =$B26*Inputs!$B$15*Curves!$C$13 -> 49401.063 | AG26: =$B26*Inputs!$B$15*Curves!$C$14 -> 57406.222 | AH26: =$B26*Inputs!$B$15*Curves!$C$15 -> 40000 | AI26: =$B26*Inputs!$B$15*Curves!$C$16 -> 40000 | AJ26: =$B26*Inputs!$B$15*Curves!$C$17 -> 40000 | AK26: =$B26*Inputs!$B$15*Curves!$C$18 -> 10000 | AL26: =$B26*Inputs!$B$15*Curves!$C$19 -> 10000
A27: =Acquisition_Plan!A26 -> 2027-11-23 | B27: =Acquisition_Plan!D26+Acquisition_Plan!F26+Acquisition_Plan!E26 -> 800000 | C27: 0 | D27: 0 | E27: 0 | F27: 0 | G27: 0 | H27: 0 | I27: 0 | J27: 0 | K27: 0 | L27: 0 | M27: 0 | N27: 0 | O27: 0 | P27: 0 | Q27: 0 | R27: 0 | S27: 0 | T27: 0 | U27: 0 | V27: 0 | W27: 0 | X27: 0 | Y27: =$B27*Inputs!$B$15*Curves!$C$5 -> 631870 | Z27: =$B27*Inputs!$B$15*Curves!$C$6 -> 301297.26 | AA27: =$B27*Inputs!$B$15*Curves!$C$7 -> 193134.66 | AB27: =$B27*Inputs!$B$15*Curves!$C$8 -> 135881.81 | AC27: =$B27*Inputs!$B$15*Curves!$C$9 -> 80785.789 | AD27: =$B27*Inputs!$B$15*Curves!$C$10 -> 72418.454 | AE27: =$B27*Inputs!$B$15*Curves!$C$11 -> 62543.8 | AF27: =$B27*Inputs!$B$15*Curves!$C$12 -> 55260.94 | AG27: =$B27*Inputs!$B$15*Curves!$C$13 -> 49401.063 | AH27: =$B27*Inputs!$B$15*Curves!$C$14 -> 57406.222 | AI27: =$B27*Inputs!$B$15*Curves!$C$15 -> 40000 | AJ27: =$B27*Inputs!$B$15*Curves!$C$16 -> 40000 | AK27: =$B27*Inputs!$B$15*Curves!$C$17 -> 40000 | AL27: =$B27*Inputs!$B$15*Curves!$C$18 -> 10000
A28: =Acquisition_Plan!A27 -> 2027-12-23 | B28: =Acquisition_Plan!D27+Acquisition_Plan!F27+Acquisition_Plan!E27 -> 800000 | C28: 0 | D28: 0 | E28: 0 | F28: 0 | G28: 0 | H28: 0 | I28: 0 | J28: 0 | K28: 0 | L28: 0 | M28: 0 | N28: 0 | O28: 0 | P28: 0 | Q28: 0 | R28: 0 | S28: 0 | T28: 0 | U28: 0 | V28: 0 | W28: 0 | X28: 0 | Y28: 0 | Z28: =$B28*Inputs!$B$15*Curves!$C$5 -> 631870 | AA28: =$B28*Inputs!$B$15*Curves!$C$6 -> 301297.26 | AB28: =$B28*Inputs!$B$15*Curves!$C$7 -> 193134.66 | AC28: =$B28*Inputs!$B$15*Curves!$C$8 -> 135881.81 | AD28: =$B28*Inputs!$B$15*Curves!$C$9 -> 80785.789 | AE28: =$B28*Inputs!$B$15*Curves!$C$10 -> 72418.454 | AF28: =$B28*Inputs!$B$15*Curves!$C$11 -> 62543.8 | AG28: =$B28*Inputs!$B$15*Curves!$C$12 -> 55260.94 | AH28: =$B28*Inputs!$B$15*Curves!$C$13 -> 49401.063 | AI28: =$B28*Inputs!$B$15*Curves!$C$14 -> 57406.222 | AJ28: =$B28*Inputs!$B$15*Curves!$C$15 -> 40000 | AK28: =$B28*Inputs!$B$15*Curves!$C$16 -> 40000 | AL28: =$B28*Inputs!$B$15*Curves!$C$17 -> 40000
A29: =Acquisition_Plan!A28 -> 2028-01-22 | B29: =Acquisition_Plan!D28+Acquisition_Plan!F28+Acquisition_Plan!E28 -> 800000 | C29: 0 | D29: 0 | E29: 0 | F29: 0 | G29: 0 | H29: 0 | I29: 0 | J29: 0 | K29: 0 | L29: 0 | M29: 0 | N29: 0 | O29: 0 | P29: 0 | Q29: 0 | R29: 0 | S29: 0 | T29: 0 | U29: 0 | V29: 0 | W29: 0 | X29: 0 | Y29: 0 | Z29: 0 | AA29: =$B29*Inputs!$B$15*Curves!$C$5 -> 631870 | AB29: =$B29*Inputs!$B$15*Curves!$C$6 -> 301297.26 | AC29: =$B29*Inputs!$B$15*Curves!$C$7 -> 193134.66 | AD29: =$B29*Inputs!$B$15*Curves!$C$8 -> 135881.81 | AE29: =$B29*Inputs!$B$15*Curves!$C$9 -> 80785.789 | AF29: =$B29*Inputs!$B$15*Curves!$C$10 -> 72418.454 | AG29: =$B29*Inputs!$B$15*Curves!$C$11 -> 62543.8 | AH29: =$B29*Inputs!$B$15*Curves!$C$12 -> 55260.94 | AI29: =$B29*Inputs!$B$15*Curves!$C$13 -> 49401.063 | AJ29: =$B29*Inputs!$B$15*Curves!$C$14 -> 57406.222 | AK29: =$B29*Inputs!$B$15*Curves!$C$15 -> 40000 | AL29: =$B29*Inputs!$B$15*Curves!$C$16 -> 40000
A30: =Acquisition_Plan!A29 -> 2028-02-21 | B30: =Acquisition_Plan!D29+Acquisition_Plan!F29+Acquisition_Plan!E29 -> 800000 | C30: 0 | D30: 0 | E30: 0 | F30: 0 | G30: 0 | H30: 0 | I30: 0 | J30: 0 | K30: 0 | L30: 0 | M30: 0 | N30: 0 | O30: 0 | P30: 0 | Q30: 0 | R30: 0 | S30: 0 | T30: 0 | U30: 0 | V30: 0 | W30: 0 | X30: 0 | Y30: 0 | Z30: 0 | AA30: 0 | AB30: =$B30*Inputs!$B$15*Curves!$C$5 -> 631870 | AC30: =$B30*Inputs!$B$15*Curves!$C$6 -> 301297.26 | AD30: =$B30*Inputs!$B$15*Curves!$C$7 -> 193134.66 | AE30: =$B30*Inputs!$B$15*Curves!$C$8 -> 135881.81 | AF30: =$B30*Inputs!$B$15*Curves!$C$9 -> 80785.789 | AG30: =$B30*Inputs!$B$15*Curves!$C$10 -> 72418.454 | AH30: =$B30*Inputs!$B$15*Curves!$C$11 -> 62543.8 | AI30: =$B30*Inputs!$B$15*Curves!$C$12 -> 55260.94 | AJ30: =$B30*Inputs!$B$15*Curves!$C$13 -> 49401.063 | AK30: =$B30*Inputs!$B$15*Curves!$C$14 -> 57406.222 | AL30: =$B30*Inputs!$B$15*Curves!$C$15 -> 40000
A31: =Acquisition_Plan!A30 -> 2028-03-22 | B31: =Acquisition_Plan!D30+Acquisition_Plan!F30+Acquisition_Plan!E30 -> 800000 | C31: 0 | D31: 0 | E31: 0 | F31: 0 | G31: 0 | H31: 0 | I31: 0 | J31: 0 | K31: 0 | L31: 0 | M31: 0 | N31: 0 | O31: 0 | P31: 0 | Q31: 0 | R31: 0 | S31: 0 | T31: 0 | U31: 0 | V31: 0 | W31: 0 | X31: 0 | Y31: 0 | Z31: 0 | AA31: 0 | AB31: 0 | AC31: =$B31*Inputs!$B$15*Curves!$C$5 -> 631870 | AD31: =$B31*Inputs!$B$15*Curves!$C$6 -> 301297.26 | AE31: =$B31*Inputs!$B$15*Curves!$C$7 -> 193134.66 | AF31: =$B31*Inputs!$B$15*Curves!$C$8 -> 135881.81 | AG31: =$B31*Inputs!$B$15*Curves!$C$9 -> 80785.789 | AH31: =$B31*Inputs!$B$15*Curves!$C$10 -> 72418.454 | AI31: =$B31*Inputs!$B$15*Curves!$C$11 -> 62543.8 | AJ31: =$B31*Inputs!$B$15*Curves!$C$12 -> 55260.94 | AK31: =$B31*Inputs!$B$15*Curves!$C$13 -> 49401.063 | AL31: =$B31*Inputs!$B$15*Curves!$C$14 -> 57406.222
A32: =Acquisition_Plan!A31 -> 2028-04-21 | B32: =Acquisition_Plan!D31+Acquisition_Plan!F31+Acquisition_Plan!E31 -> 800000 | C32: 0 | D32: 0 | E32: 0 | F32: 0 | G32: 0 | H32: 0 | I32: 0 | J32: 0 | K32: 0 | L32: 0 | M32: 0 | N32: 0 | O32: 0 | P32: 0 | Q32: 0 | R32: 0 | S32: 0 | T32: 0 | U32: 0 | V32: 0 | W32: 0 | X32: 0 | Y32: 0 | Z32: 0 | AA32: 0 | AB32: 0 | AC32: 0 | AD32: =$B32*Inputs!$B$15*Curves!$C$5 -> 631870 | AE32: =$B32*Inputs!$B$15*Curves!$C$6 -> 301297.26 | AF32: =$B32*Inputs!$B$15*Curves!$C$7 -> 193134.66 | AG32: =$B32*Inputs!$B$15*Curves!$C$8 -> 135881.81 | AH32: =$B32*Inputs!$B$15*Curves!$C$9 -> 80785.789 | AI32: =$B32*Inputs!$B$15*Curves!$C$10 -> 72418.454 | AJ32: =$B32*Inputs!$B$15*Curves!$C$11 -> 62543.8 | AK32: =$B32*Inputs!$B$15*Curves!$C$12 -> 55260.94 | AL32: =$B32*Inputs!$B$15*Curves!$C$13 -> 49401.063
A33: =Acquisition_Plan!A32 -> 2028-05-21 | B33: =Acquisition_Plan!D32+Acquisition_Plan!F32+Acquisition_Plan!E32 -> 800000 | C33: 0 | D33: 0 | E33: 0 | F33: 0 | G33: 0 | H33: 0 | I33: 0 | J33: 0 | K33: 0 | L33: 0 | M33: 0 | N33: 0 | O33: 0 | P33: 0 | Q33: 0 | R33: 0 | S33: 0 | T33: 0 | U33: 0 | V33: 0 | W33: 0 | X33: 0 | Y33: 0 | Z33: 0 | AA33: 0 | AB33: 0 | AC33: 0 | AD33: 0 | AE33: =$B33*Inputs!$B$15*Curves!$C$5 -> 631870 | AF33: =$B33*Inputs!$B$15*Curves!$C$6 -> 301297.26 | AG33: =$B33*Inputs!$B$15*Curves!$C$7 -> 193134.66 | AH33: =$B33*Inputs!$B$15*Curves!$C$8 -> 135881.81 | AI33: =$B33*Inputs!$B$15*Curves!$C$9 -> 80785.789 | AJ33: =$B33*Inputs!$B$15*Curves!$C$10 -> 72418.454 | AK33: =$B33*Inputs!$B$15*Curves!$C$11 -> 62543.8 | AL33: =$B33*Inputs!$B$15*Curves!$C$12 -> 55260.94
A34: =Acquisition_Plan!A33 -> 2028-06-20 | B34: =Acquisition_Plan!D33+Acquisition_Plan!F33+Acquisition_Plan!E33 -> 800000 | C34: 0 | D34: 0 | E34: 0 | F34: 0 | G34: 0 | H34: 0 | I34: 0 | J34: 0 | K34: 0 | L34: 0 | M34: 0 | N34: 0 | O34: 0 | P34: 0 | Q34: 0 | R34: 0 | S34: 0 | T34: 0 | U34: 0 | V34: 0 | W34: 0 | X34: 0 | Y34: 0 | Z34: 0 | AA34: 0 | AB34: 0 | AC34: 0 | AD34: 0 | AE34: 0 | AF34: =$B34*Inputs!$B$15*Curves!$C$5 -> 631870 | AG34: =$B34*Inputs!$B$15*Curves!$C$6 -> 301297.26 | AH34: =$B34*Inputs!$B$15*Curves!$C$7 -> 193134.66 | AI34: =$B34*Inputs!$B$15*Curves!$C$8 -> 135881.81 | AJ34: =$B34*Inputs!$B$15*Curves!$C$9 -> 80785.789 | AK34: =$B34*Inputs!$B$15*Curves!$C$10 -> 72418.454 | AL34: =$B34*Inputs!$B$15*Curves!$C$11 -> 62543.8
A35: =Acquisition_Plan!A34 -> 2028-07-20 | B35: =Acquisition_Plan!D34+Acquisition_Plan!F34+Acquisition_Plan!E34 -> 800000 | C35: 0 | D35: 0 | E35: 0 | F35: 0 | G35: 0 | H35: 0 | I35: 0 | J35: 0 | K35: 0 | L35: 0 | M35: 0 | N35: 0 | O35: 0 | P35: 0 | Q35: 0 | R35: 0 | S35: 0 | T35: 0 | U35: 0 | V35: 0 | W35: 0 | X35: 0 | Y35: 0 | Z35: 0 | AA35: 0 | AB35: 0 | AC35: 0 | AD35: 0 | AE35: 0 | AF35: 0 | AG35: =$B35*Inputs!$B$15*Curves!$C$5 -> 631870 | AH35: =$B35*Inputs!$B$15*Curves!$C$6 -> 301297.26 | AI35: =$B35*Inputs!$B$15*Curves!$C$7 -> 193134.66 | AJ35: =$B35*Inputs!$B$15*Curves!$C$8 -> 135881.81 | AK35: =$B35*Inputs!$B$15*Curves!$C$9 -> 80785.789 | AL35: =$B35*Inputs!$B$15*Curves!$C$10 -> 72418.454
A36: =Acquisition_Plan!A35 -> 2028-08-19 | B36: =Acquisition_Plan!D35+Acquisition_Plan!F35+Acquisition_Plan!E35 -> 800000 | C36: 0 | D36: 0 | E36: 0 | F36: 0 | G36: 0 | H36: 0 | I36: 0 | J36: 0 | K36: 0 | L36: 0 | M36: 0 | N36: 0 | O36: 0 | P36: 0 | Q36: 0 | R36: 0 | S36: 0 | T36: 0 | U36: 0 | V36: 0 | W36: 0 | X36: 0 | Y36: 0 | Z36: 0 | AA36: 0 | AB36: 0 | AC36: 0 | AD36: 0 | AE36: 0 | AF36: 0 | AG36: 0 | AH36: =$B36*Inputs!$B$15*Curves!$C$5 -> 631870 | AI36: =$B36*Inputs!$B$15*Curves!$C$6 -> 301297.26 | AJ36: =$B36*Inputs!$B$15*Curves!$C$7 -> 193134.66 | AK36: =$B36*Inputs!$B$15*Curves!$C$8 -> 135881.81 | AL36: =$B36*Inputs!$B$15*Curves!$C$9 -> 80785.789
A37: =Acquisition_Plan!A36 -> 2028-09-18 | B37: =Acquisition_Plan!D36+Acquisition_Plan!F36+Acquisition_Plan!E36 -> 800000 | C37: 0 | D37: 0 | E37: 0 | F37: 0 | G37: 0 | H37: 0 | I37: 0 | J37: 0 | K37: 0 | L37: 0 | M37: 0 | N37: 0 | O37: 0 | P37: 0 | Q37: 0 | R37: 0 | S37: 0 | T37: 0 | U37: 0 | V37: 0 | W37: 0 | X37: 0 | Y37: 0 | Z37: 0 | AA37: 0 | AB37: 0 | AC37: 0 | AD37: 0 | AE37: 0 | AF37: 0 | AG37: 0 | AH37: 0 | AI37: =$B37*Inputs!$B$15*Curves!$C$5 -> 631870 | AJ37: =$B37*Inputs!$B$15*Curves!$C$6 -> 301297.26 | AK37: =$B37*Inputs!$B$15*Curves!$C$7 -> 193134.66 | AL37: =$B37*Inputs!$B$15*Curves!$C$8 -> 135881.81
A38: =Acquisition_Plan!A37 -> 2028-10-18 | B38: =Acquisition_Plan!D37+Acquisition_Plan!F37+Acquisition_Plan!E37 -> 800000 | C38: 0 | D38: 0 | E38: 0 | F38: 0 | G38: 0 | H38: 0 | I38: 0 | J38: 0 | K38: 0 | L38: 0 | M38: 0 | N38: 0 | O38: 0 | P38: 0 | Q38: 0 | R38: 0 | S38: 0 | T38: 0 | U38: 0 | V38: 0 | W38: 0 | X38: 0 | Y38: 0 | Z38: 0 | AA38: 0 | AB38: 0 | AC38: 0 | AD38: 0 | AE38: 0 | AF38: 0 | AG38: 0 | AH38: 0 | AI38: 0 | AJ38: =$B38*Inputs!$B$15*Curves!$C$5 -> 631870 | AK38: =$B38*Inputs!$B$15*Curves!$C$6 -> 301297.26 | AL38: =$B38*Inputs!$B$15*Curves!$C$7 -> 193134.66
A39: =Acquisition_Plan!A38 -> 2028-11-17 | B39: =Acquisition_Plan!D38+Acquisition_Plan!F38+Acquisition_Plan!E38 -> 800000 | C39: 0 | D39: 0 | E39: 0 | F39: 0 | G39: 0 | H39: 0 | I39: 0 | J39: 0 | K39: 0 | L39: 0 | M39: 0 | N39: 0 | O39: 0 | P39: 0 | Q39: 0 | R39: 0 | S39: 0 | T39: 0 | U39: 0 | V39: 0 | W39: 0 | X39: 0 | Y39: 0 | Z39: 0 | AA39: 0 | AB39: 0 | AC39: 0 | AD39: 0 | AE39: 0 | AF39: 0 | AG39: 0 | AH39: 0 | AI39: 0 | AJ39: 0 | AK39: =$B39*Inputs!$B$15*Curves!$C$5 -> 631870 | AL39: =$B39*Inputs!$B$15*Curves!$C$6 -> 301297.26
A40: =Acquisition_Plan!A39 -> 2028-12-17 | B40: =Acquisition_Plan!D39+Acquisition_Plan!F39+Acquisition_Plan!E39 -> 800000 | C40: 0 | D40: 0 | E40: 0 | F40: 0 | G40: 0 | H40: 0 | I40: 0 | J40: 0 | K40: 0 | L40: 0 | M40: 0 | N40: 0 | O40: 0 | P40: 0 | Q40: 0 | R40: 0 | S40: 0 | T40: 0 | U40: 0 | V40: 0 | W40: 0 | X40: 0 | Y40: 0 | Z40: 0 | AA40: 0 | AB40: 0 | AC40: 0 | AD40: 0 | AE40: 0 | AF40: 0 | AG40: 0 | AH40: 0 | AI40: 0 | AJ40: 0 | AK40: 0 | AL40: =$B40*Inputs!$B$15*Curves!$C$5 -> 631870
A41: TOTAL | C41: =SUM(C5:C40) -> 157967.5 | D41: =SUM(D5:D40) -> 272783.69 | E41: =SUM(E5:E40) -> 379390.31 | F41: =SUM(F5:F40) -> 444262.76 | G41: =SUM(G5:G40) -> 564006.48 | H41: =SUM(H5:H40) -> 633314.98 | I41: =SUM(I5:I40) -> 761651.78 | J41: =SUM(J5:J40) -> 838549.54 | ... AL41: =SUM(AL5:AL40) -> 1938125

Sheet New_Cohort_WD
A1: New Cohort Withdrawals (All Sources)
A2: Spend = CC + Cash + PVX
A4: Cohort | B4: Spend | C4: M0 | D4: M1 | E4: M2 | F4: M3 | G4: M4 | H4: M5 | I4: M6 | J4: M7 | K4: M8 | L4: M9 | M4: M10 | N4: M11 | O4: M12 | P4: M13 | Q4: M14 | R4: M15 | S4: M16 | T4: M17 | U4: M18 | V4: M19 | W4: M20 | X4: M21 | Y4: M22 | Z4: M23 | AA4: M24 | AB4: M25 | AC4: M26 | AD4: M27 | AE4: M28 | AF4: M29 | AG4: M30 | AH4: M31 | AI4: M32 | AJ4: M33 | AK4: M34 | AL4: M35
A5: =Acquisition_Plan!A4 -> 2026-02-01 | B5: =Acquisition_Plan!D4+Acquisition_Plan!F4+Acquisition_Plan!E4 -> 200000 | C5: =$B5*Inputs!$B$15*Inputs!$B$16*Curves!$E$5 -> 21388.026 | D5: =$B5*Inputs!$B$15*Inputs!$B$16*Curves!$E$6 -> 23533.985 | E5: =$B5*Inputs!$B$15*Inputs!$B$16*Curves!$E$7 -> 13209.701 | F5: =$B5*Inputs!$B$15*Inputs!$B$16*Curves!$E$8 -> 14254.595 | G5: =$B5*Inputs!$B$15*Inputs!$B$16*Curves!$E$9 -> 14323.857 | H5: =$B5*Inputs!$B$15*Inputs!$B$16*Curves!$E$10 -> 10549.744 | I5: =$B5*Inputs!$B$15*Inputs!$B$16*Curves!$E$11 -> 13887.837 | J5: =$B5*Inputs!$B$15*Inputs!$B$16*Curves!$E$12 -> 6095.2553 | K5: =$B5*Inputs!$B$15*Inputs!$B$16*Curves!$E$13 -> 3939.9265 | L5: =$B5*Inputs!$B$15*Inputs!$B$16*Curves!$E$14 -> 5917.0736 | M5: =$B5*Inputs!$B$15*Inputs!$B$16*Curves!$E$15 -> 3100 | N5: =$B5*Inputs!$B$15*Inputs!$B$16*Curves!$E$16 -> 3100 | O5: =$B5*Inputs!$B$15*Inputs!$B$16*Curves!$E$17 -> 3100 | P5: =$B5*Inputs!$B$15*Inputs!$B$16*Curves!$E$18 -> 775 | Q5: =$B5*Inputs!$B$15*Inputs!$B$16*Curves!$E$19 -> 775 | R5: =$B5*Inputs!$B$15*Inputs!$B$16*Curves!$E$20 -> 775 | S5: =$B5*Inputs!$B$15*Inputs!$B$16*Curves!$E$21 -> 775 | T5: =$B5*Inputs!$B$15*Inputs!$B$16*Curves!$E$22 -> 775 | U5: =$B5*Inputs!$B$15*Inputs!$B$16*Curves!$E$23 -> 775 | V5: =$B5*Inputs!$B$15*Inputs!$B$16*Curves!$E$24 -> 775 | W5: =$B5*Inputs!$B$15*Inputs!$B$16*Curves!$E$25 -> 775 | X5: =$B5*Inputs!$B$15*Inputs!$B$16*Curves!$E$26 -> 775 | Y5: =$B5*Inputs!$B$15*Inputs!$B$16*Curves!$E$27 -> 775 | Z5: =$B5*Inputs!$B$15*Inputs!$B$16*Curves!$E$28 -> 775 | AA5: =$B5*Inputs!$B$15*Inputs!$B$16*Curves!$E$29 -> 775 | AB5: =$B5*Inputs!$B$15*Inputs!$B$16*Curves!$E$30 -> 775 | AC5: =$B5*Inputs!$B$15*Inputs!$B$16*Curves!$E$31 -> 775 | AD5: =$B5*Inputs!$B$15*Inputs!$B$16*Curves!$E$32 -> 775 | AE5: =$B5*Inputs!$B$15*Inputs!$B$16*Curves!$E$33 -> 775 | AF5: =$B5*Inputs!$B$15*Inputs!$B$16*Curves!$E$34 -> 775 | AG5: =$B5*Inputs!$B$15*Inputs!$B$16*Curves!$E$35 -> 775 | AH5: =$B5*Inputs!$B$15*Inputs!$B$16*Curves!$E$36 -> 775 | AI5: =$B5*Inputs!$B$15*Inputs!$B$16*Curves!$E$37 -> 775 | AJ5: =$B5*Inputs!$B$15*Inputs!$B$16*Curves!$E$38 -> 775 | AK5: =$B5*Inputs!$B$15*Inputs!$B$16*Curves!$E$39 -> 775 | AL5: =$B5*Inputs!$B$15*Inputs!$B$16*Curves!$E$40 -> 775
A6: =Acquisition_Plan!A5 -> 2026-03-03 | B6: =Acquisition_Plan!D5+Acquisition_Plan!F5+Acquisition_Plan!E5 -> 250000 | C6: 0 | D6: =$B6*Inputs!$B$15*Inputs!$B$16*Curves!$E$5 -> 26735.032 | E6: =$B6*Inputs!$B$15*Inputs!$B$16*Curves!$E$6 -> 29417.481 | F6: =$B6*Inputs!$B$15*Inputs!$B$16*Curves!$E$7 -> 16512.126 | G6: =$B6*Inputs!$B$15*Inputs!$B$16*Curves!$E$8 -> 17818.244 | H6: =$B6*Inputs!$B$15*Inputs!$B$16*Curves!$E$9 -> 17904.822 | I6: =$B6*Inputs!$B$15*Inputs!$B$16*Curves!$E$10 -> 13187.18 | J6: =$B6*Inputs!$B$15*Inputs!$B$16*Curves!$E$11 -> 17359.797 | K6: =$B6*Inputs!$B$15*Inputs!$B$16*Curves!$E$12 -> 7619.0692 | L6: =$B6*Inputs!$B$15*Inputs!$B$16*Curves!$E$13 -> 4924.9081 | M6: =$B6*Inputs!$B$15*Inputs!$B$16*Curves!$E$14 -> 7396.342 | N6: =$B6*Inputs!$B$15*Inputs!$B$16*Curves!$E$15 -> 3875 | O6: =$B6*Inputs!$B$15*Inputs!$B$16*Curves!$E$16 -> 3875 | P6: =$B6*Inputs!$B$15*Inputs!$B$16*Curves!$E$17 -> 3875 | Q6: =$B6*Inputs!$B$15*Inputs!$B$16*Curves!$E$18 -> 968.75 | R6: =$B6*Inputs!$B$15*Inputs!$B$16*Curves!$E$19 -> 968.75 | S6: =$B6*Inputs!$B$15*Inputs!$B$16*Curves!$E$20 -> 968.75 | T6: =$B6*Inputs!$B$15*Inputs!$B$16*Curves!$E$21 -> 968.75 | U6: =$B6*Inputs!$B$15*Inputs!$B$16*Curves!$E$22 -> 968.75 | V6: =$B6*Inputs!$B$15*Inputs!$B$16*Curves!$E$23 -> 968.75 | W6: =$B6*Inputs!$B$15*Inputs!$B$16*Curves!$E$24 -> 968.75 | X6: =$B6*Inputs!$B$15*Inputs!$B$16*Curves!$E$25 -> 968.75 | Y6: =$B6*Inputs!$B$15*Inputs!$B$16*Curves!$E$26 -> 968.75 | Z6: =$B6*Inputs!$B$15*Inputs!$B$16*Curves!$E$27 -> 968.75 | AA6: =$B6*Inputs!$B$15*Inputs!$B$16*Curves!$E$28 -> 968.75 | AB6: =$B6*Inputs!$B$15*Inputs!$B$16*Curves!$E$29 -> 968.75 | AC6: =$B6*Inputs!$B$15*Inputs!$B$16*Curves!$E$30 -> 968.75 | AD6: =$B6*Inputs!$B$15*Inputs!$B$16*Curves!$E$31 -> 968.75 | AE6: =$B6*Inputs!$B$15*Inputs!$B$16*Curves!$E$32 -> 968.75 | AF6: =$B6*Inputs!$B$15*Inputs!$B$16*Curves!$E$33 -> 968.75 | AG6: =$B6*Inputs!$B$15*Inputs!$B$16*Curves!$E$34 -> 968.75 | AH6: =$B6*Inputs!$B$15*Inputs!$B$16*Curves!$E$35 -> 968.75 | AI6: =$B6*Inputs!$B$15*Inputs!$B$16*Curves!$E$36 -> 968.75 | AJ6: =$B6*Inputs!$B$15*Inputs!$B$16*Curves!$E$37 -> 968.75 | AK6: =$B6*Inputs!$B$15*Inputs!$B$16*Curves!$E$38 -> 968.75 | AL6: =$B6*Inputs!$B$15*Inputs!$B$16*Curves!$E$39 -> 968.75
A7: =Acquisition_Plan!A6 -> 2026-04-02 | B7: =Acquisition_Plan!D6+Acquisition_Plan!F6+Acquisition_Plan!E6 -> 300000 | C7: 0 | D7: 0 | E7: =$B7*Inputs!$B$15*Inputs!$B$16*Curves!$E$5 -> 32082.039 | F7: =$B7*Inputs!$B$15*Inputs!$B$16*Curves!$E$6 -> 35300.977 | G7: =$B7*Inputs!$B$15*Inputs!$B$16*Curves!$E$7 -> 19814.551 | H7: =$B7*Inputs!$B$15*Inputs!$B$16*Curves!$E$8 -> 21381.892 | I7: =$B7*Inputs!$B$15*Inputs!$B$16*Curves!$E$9 -> 21485.786 | J7: =$B7*Inputs!$B$15*Inputs!$B$16*Curves!$E$10 -> 15824.616 | K7: =$B7*Inputs!$B$15*Inputs!$B$16*Curves!$E$11 -> 20831.756 | L7: =$B7*Inputs!$B$15*Inputs!$B$16*Curves!$E$12 -> 9142.883 | M7: =$B7*Inputs!$B$15*Inputs!$B$16*Curves!$E$13 -> 5909.8897 | N7: =$B7*Inputs!$B$15*Inputs!$B$16*Curves!$E$14 -> 8875.6104 | O7: =$B7*Inputs!$B$15*Inputs!$B$16*Curves!$E$15 -> 4650 | P7: =$B7*Inputs!$B$15*Inputs!$B$16*Curves!$E$16 -> 4650 | Q7: =$B7*Inputs!$B$15*Inputs!$B$16*Curves!$E$17 -> 4650 | R7: =$B7*Inputs!$B$15*Inputs!$B$16*Curves!$E$18 -> 1162.5 | S7: =$B7*Inputs!$B$15*Inputs!$B$16*Curves!$E$19 -> 1162.5 | T7: =$B7*Inputs!$B$15*Inputs!$B$16*Curves!$E$20 -> 1162.5 | U7: =$B7*Inputs!$B$15*Inputs!$B$16*Curves!$E$21 -> 1162.5 | V7: =$B7*Inputs!$B$15*Inputs!$B$16*Curves!$E$22 -> 1162.5 | W7: =$B7*Inputs!$B$15*Inputs!$B$16*Curves!$E$23 -> 1162.5 | X7: =$B7*Inputs!$B$15*Inputs!$B$16*Curves!$E$24 -> 1162.5 | Y7: =$B7*Inputs!$B$15*Inputs!$B$16*Curves!$E$25 -> 1162.5 | Z7: =$B7*Inputs!$B$15*Inputs!$B$16*Curves!$E$26 -> 1162.5 | AA7: =$B7*Inputs!$B$15*Inputs!$B$16*Curves!$E$27 -> 1162.5 | AB7: =$B7*Inputs!$B$15*Inputs!$B$16*Curves!$E$28 -> 1162.5 | AC7: =$B7*Inputs!$B$15*Inputs!$B$16*Curves!$E$29 -> 1162.5 | AD7: =$B7*Inputs!$B$15*Inputs!$B$16*Curves!$E$30 -> 1162.5 | AE7: =$B7*Inputs!$B$15*Inputs!$B$16*Curves!$E$31 -> 1162.5 | AF7: =$B7*Inputs!$B$15*Inputs!$B$16*Curves!$E$32 -> 1162.5 | AG7: =$B7*Inputs!$B$15*Inputs!$B$16*Curves!$E$33 -> 1162.5 | AH7: =$B7*Inputs!$B$15*Inputs!$B$16*Curves!$E$34 -> 1162.5 | AI7: =$B7*Inputs!$B$15*Inputs!$B$16*Curves!$E$35 -> 1162.5 | AJ7: =$B7*Inputs!$B$15*Inputs!$B$16*Curves!$E$36 -> 1162.5 | AK7: =$B7*Inputs!$B$15*Inputs!$B$16*Curves!$E$37 -> 1162.5 | AL7: =$B7*Inputs!$B$15*Inputs!$B$16*Curves!$E$38 -> 1162.5
A8: =Acquisition_Plan!A7 -> 2026-05-02 | B8: =Acquisition_Plan!D7+Acquisition_Plan!F7+Acquisition_Plan!E7 -> 300000 | C8: 0 | D8: 0 | E8: 0 | F8: =$B8*Inputs!$B$15*Inputs!$B$16*Curves!$E$5 -> 32082.039 | G8: =$B8*Inputs!$B$15*Inputs!$B$16*Curves!$E$6 -> 35300.977 | H8: =$B8*Inputs!$B$15*Inputs!$B$16*Curves!$E$7 -> 19814.551 | I8: =$B8*Inputs!$B$15*Inputs!$B$16*Curves!$E$8 -> 21381.892 | J8: =$B8*Inputs!$B$15*Inputs!$B$16*Curves!$E$9 -> 21485.786 | K8: =$B8*Inputs!$B$15*Inputs!$B$16*Curves!$E$10 -> 15824.616 | L8: =$B8*Inputs!$B$15*Inputs!$B$16*Curves!$E$11 -> 20831.756 | M8: =$B8*Inputs!$B$15*Inputs!$B$16*Curves!$E$12 -> 9142.883 | N8: =$B8*Inputs!$B$15*Inputs!$B$16*Curves!$E$13 -> 5909.8897 | O8: =$B8*Inputs!$B$15*Inputs!$B$16*Curves!$E$14 -> 8875.6104 | P8: =$B8*Inputs!$B$15*Inputs!$B$16*Curves!$E$15 -> 4650 | Q8: =$B8*Inputs!$B$15*Inputs!$B$16*Curves!$E$16 -> 4650 | R8: =$B8*Inputs!$B$15*Inputs!$B$16*Curves!$E$17 -> 4650 | S8: =$B8*Inputs!$B$15*Inputs!$B$16*Curves!$E$18 -> 1162.5 | T8: =$B8*Inputs!$B$15*Inputs!$B$16*Curves!$E$19 -> 1162.5 | U8: =$B8*Inputs!$B$15*Inputs!$B$16*Curves!$E$20 -> 1162.5 | V8: =$B8*Inputs!$B$15*Inputs!$B$16*Curves!$E$21 -> 1162.5 | W8: =$B8*Inputs!$B$15*Inputs!$B$16*Curves!$E$22 -> 1162.5 | X8: =$B8*Inputs!$B$15*Inputs!$B$16*Curves!$E$23 -> 1162.5 | Y8: =$B8*Inputs!$B$15*Inputs!$B$16*Curves!$E$24 -> 1162.5 | Z8: =$B8*Inputs!$B$15*Inputs!$B$16*Curves!$E$25 -> 1162.5 | AA8: =$B8*Inputs!$B$15*Inputs!$B$16*Curves!$E$26 -> 1162.5 | AB8: =$B8*Inputs!$B$15*Inputs!$B$16*Curves!$E$27 -> 1162.5 | AC8: =$B8*Inputs!$B$15*Inputs!$B$16*Curves!$E$28 -> 1162.5 | AD8: =$B8*Inputs!$B$15*Inputs!$B$16*Curves!$E$29 -> 1162.5 | AE8: =$B8*Inputs!$B$15*Inputs!$B$16*Curves!$E$30 -> 1162.5 | AF8: =$B8*Inputs!$B$15*Inputs!$B$16*Curves!$E$31 -> 1162.5 | AG8: =$B8*Inputs!$B$15*Inputs!$B$16*Curves!$E$32 -> 1162.5 | AH8: =$B8*Inputs!$B$15*Inputs!$B$16*Curves!$E$33 -> 1162.5 | AI8: =$B8*Inputs!$B$15*Inputs!$B$16*Curves!$E$34 -> 1162.5 | AJ8: =$B8*Inputs!$B$15*Inputs!$B$16*Curves!$E$35 -> 1162.5 | AK8: =$B8*Inputs!$B$15*Inputs!$B$16*Curves!$E$36 -> 1162.5 | AL8: =$B8*Inputs!$B$15*Inputs!$B$16*Curves!$E$37 -> 1162.5
